Workbook
Name Bucket: #REF!
Name DeliverabilityOptions: [1]Lists!#REF!
Name EndMonth: #REF!
Name LocalAreaOptions: [2]Lists!$B$11:$B$21
Name Month: #REF!
Name RA_Capacity: #REF!
Name SchedulingID: #REF!
Name StartMonth: #REF!
Name Submittal: [3]Lists!$A$2:$A$3
Name Zone: #REF!

Sheet About
A1: PTCF Peak Time Capacity Factors | B1: Louisiana
A3: Source: | B3: California Market | E3: Texas Market | H3: Southwest Market
B4: California Independent System Operator | E4: Electric Reliability Council of Texas | H4: Southwest Power Pool
B5: 2020 | E5: 2016 | H5: 2019
B6: Final 2020 Net Qualifying Capacity for Resource Adequacy Resources | E6: CDR Peak Values for Solar PV and Wind by Season | H6: Solar and Wind ELCC Accreditation
B7: http://www.caiso.com/Documents/NetQualifyingCapacityList-2020.xls | E7: http://www.ercot.com/gridinfo/resource | H7: https://www.spp.org/documents/61025/elcc%20solar%20and%20wind%20accreditation.pdf
B8: 2020 Technology Factors
B10: Midwest Market | E10: Mid Atlantic Market | H10: California Market Energy
B11: Midcontinent Independent System Operator | E11: PJM | H11: CAISO
B12: 2019 | E12: 2017 | H12: 2020
B13: Planning Year 2020-2021 Wind & Solar Capacity Credit | E13: Class Average Capacity Factors | H13: 2019 Annual Report on Market Issues & Performance
B14: https://cdn.misoenergy.org/2020%20Wind%20&%20Solar%20Capacity%20Credit%20Report408144.pdf | E14: https://www.pjm.com/-/media/planning/res-adeq/class-average-wind-capacity-factors.ashx?la=en | H14: http://www.caiso.com/Documents/2019AnnualReportonMarketIssuesandPerformance.pdf
B15: p.16 | E15: p.5-6 | H15: Table 1.1
B17: New England Market - Solar | E17: Offshore Wind, Onshore Wind for PJM, ISO-NE, and NYISO | H17: New York Market Energy
B18: ISO New England | E18: LBNL | H18: NYISO
B19: 2015 | E19: 2018 | H19: 2020
B20: Intermittent Resource Review | E20: Estimating the Value of Offshore Wind Along the United States’ Eastern Coast | H20: 2020 Load and Capacity Data
B21: http://www.iso-ne.com/static-assets/documents/2015/12/vrwg_intermittent_resource_qual_tool_status_update_12072015.pdf | E21: https://www.nps.edu/documents/114698888/117879842/Offshore_WInd_Value_Navy_Postgraduate_School_Final.pdf/f4368eea-e0e0-4fba-a925-00f5d365b887?t=1542325871000 | H21: https://www.nyiso.com/documents/20142/2226333/2020-Gold-Book-Final-Public.pdf/9ff426ab-e325-28bc-97cf-106d792593a1
B22: pp. 4 & 7 | E22: p.27 | H22: Table I-1a
H24: New England Market Energy
H25: ISO-NE
A26: Notes | H26: 2020
A27: Peak time capacity factors are meant to represent the average availability of resources to meeting peak | H27: 2020 CELT Report
A28: during the peak hours of the year in the summer and winter seasons. | H28: https://www.iso-ne.com/system-planning/system-plans-studies/celt
H29: Table 1.5.2 Energy
A30: For renewable resources (e.g. wind and solar PV) we use values from each of the 6 U.S. regional markets.
A31: As part of the resource planning process, operators of these markets are required to assess available resources during
A32: peak hours of the year.
A34: We take factors where available from each of the markets and weight the values by the share
A35: of system load from each region to generate a weighted average peak time capacity factor
A36: for different resources across the US.

Sheet CAISO - CF
A3: 2020 ELCC Values and Technology Factors
A4: Non-Dispatchable Solar, Wind, Biomass, Cogeneration, Geothermal, and
A5: Hydro Technology Factors for Compliance Year 2020
B8: Solar PV and Solar Thermal
B9: Month | C9: CY 2020 Solar ELCC
B10: 1 | C10: 0.04
B11: 2 | C11: 0.03
B12: 3 | C12: 0.18
B13: 4 | C13: 0.15
B14: 5 | C14: 0.16
B15: 6 | C15: 0.31
B16: 7 | C16: 0.39
B17: 8 | C17: 0.27
B18: 9 | C18: 0.14
B19: 10 | C19: 0.02
B20: 11 | C20: 0.02
B21: 12 | C21: 0
B24: Wind
B25: Month | C25: CY 2020 Wind ELCC
B26: 1 | C26: 0.14
B27: 2 | C27: 0.12
B28: 3 | C28: 0.28
B29: 4 | C29: 0.25
B30: 5 | C30: 0.25
B31: 6 | C31: 0.33
B32: 7 | C32: 0.23
B33: 8 | C33: 0.21
B34: 9 | C34: 0.15
B35: 10 | C35: 0.08
B36: 11 | C36: 0.12
B37: 12 | C37: 0.13
B47: Biomass
B48: Month | C48: 2016 | D48: 2017 | E48: 2018 | F48: CY 2020 Biomass Factor
B49: 1 | C49: 0.87 | D49: 0.73 | E49: 0.85 | F49: 0.82
B50: 2 | C50: 0.91 | D50: 0.85 | E50: 0.84 | F50: 0.86
B51: 3 | C51: 0.84 | D51: 0.82 | E51: 0.86 | F51: 0.84
B52: 4 | C52: 0.76 | D52: 0.74 | E52: 0.79 | F52: 0.76
B53: 5 | C53: 0.84 | D53: 0.83 | E53: 0.83 | F53: 0.83
B54: 6 | C54: 0.92 | D54: 0.88 | E54: 0.86 | F54: 0.89
B55: 7 | C55: 0.91 | D55: 0.83 | E55: 0.87 | F55: 0.87
...

Sheet ERCOT - CF
B1: PEAK AVERAGE WIND CAPACITY PERCENTAGES, WINTER PEAK SEASONS
J2: WINDPEAKPCT Values (Weighted Averages based on Installed Wind Capacity)*
B3: Winter Peak Ave. Wind Capacity Percentages and Total Unit Capacities | J3: Winter, Panhandle | K3: Winter, Coastal | L3: Winter, Other
B4: Top Twenty Peak Hours for Each year | J4: =SUMPRODUCT(C7:C16,D7:D16)/SUM(D7:D16) -> 0.32491694 | K4: =SUMPRODUCT(E7:E16,F7:F16)/SUM(F7:F16) -> 0.42750905 | L4: =SUMPRODUCT(G7:G16,H7:H16)/SUM(H7:H16) -> 0.19171367
B5: CDR Wind Region | C5: Panhandle | E5: Coastal | G5: Other
B6: Year | C6: Capacity Contribution Percentage | D6: Capacity (MW) | E6: Capacity Contribution Percentage | F6: Capacity (MW) | G6: Capacity Contribution Percentage | H6: Capacity (MW) | J6: * The methodology for calculating WINDPEAKPCT values is outlined in ERCOT Protocol Section 3.2.6.2.2. See: http://www.ercot.com/content/wcm/current_guides/53528/03-030120_Nodal.docx
B7: 2019-2020 | C7: 0.38116302 | D7: 4197.6 | E7: 0.33964313 | F7: 2974.4 | G7: 0.27527403 | H7: 15598.8
B8: 2018-2019 | C8: 0.39806301 | D8: 4197 | E8: 0.39119188 | F8: 2610.6 | G8: 0.20963421 | H8: 14730.2
B9: 2017-2018 | C9: 0.33292465 | D9: 4197 | E9: 0.51881614 | F9: 2382.6 | G9: 0.14262171 | H9: 11996.3
B10: 2016-2017 | C10: 0.19940455 | D10: 3609 | E10: 0.79338515 | F10: 2038.4 | G10: 0.14286179 | H10: 10821.7
B11: 2015-2016 | C11: 0.28446769 | D11: 2670.5 | E11: 0.27016577 | F11: 1875.4 | G11: 0.2844107 | H11: 10494.9
B12: 2014-2015 | C12: 0.22712979 | D12: 207 | E12: 0.42284952 | F12: 1671.4 | G12: 0.10700787 | H12: 8858.8
B13: 2013-2014 | C13: 0.36173637 | D13: 207 | E13: 0.43660053 | F13: 1269.7 | G13: 0.17265001 | H13: 8789.4
B14: 2012-2013 | C14: 0.23047625 | D14: 207 | E14: 0.32465499 | F14: 1066.4 | G14: 0.16685321 | H14: 7999.2
B15: 2011-2012 | C15: 0.38469327 | D15: 207 | E15: 0.15738836 | F15: 965.6 | G15: 0.20275638 | H15: 7670.7
B16: 2010-2011 | C16: 0.34467367 | D16: 206.957 | E16: 0.48410488 | F16: 965.55 | G16: 0.14303803 | H16: 8023.935
B19: PEAK AVERAGE SOLAR CAPACITY PERCENTAGES, WINTER PEAK SEASONS
F21: SOLARPEAKPCT Value (Weighted Average based on Installed Solar Capacity) *
B22: Winter Peak Ave. Solar Capacity Percentages and Total Unit Capacities | F22: Winter
B23: Top Twenty Peak Hours for Each year | F23: =SUMPRODUCT(C25:C27,D25:D27)/SUM(D25:D27) -> 0.068617832
B24: Year | C24: Capacity Contribution Percentage | D24: Capacity (MW)
B25: 2019/2020 | C25: 0.03868493 | D25: 2020.2
B26: 2018/2019 | C26: 0.091846314 | D26: 1404
B27: 2017/2018 | C27: 0.098614238 | D27: 928.7 | F27: * The methodology for calculating SOLARPEAKPCT values is outlined in ERCOT Protocol Section 3.2.6.2.2. See: http://www.ercot.com/content/wcm/current_guides/53528/03-030120_Nodal.docx
B32: PEAK AVERAGE SOLAR CAPACITY PERCENTAGES, SUMMER PEAK SEASONS
B34: Summer Peak Ave. Solar Capacity Percentages
B35: Top Twenty Peak Hours for Each year | F35: SOLARPEAKPCT Values *
B36: Year | C36: Average Solar Cap Percentage | D36: MW Solar Capacity | F36: =SUMPRODUCT(C37:C39,D37:D39)/SUM(D37:D39) -> 0.76320678
B37: 2019 | C37: 0.73991125 | D37: 1636
B38: 2018 | C38: 0.796 | D38: 1254
B39: 2017 | C39: 0.759 | D39: 715.8
B42: PEAK AVERAGE WIND CAPACITY PERCENTAGES, SUMMER PEAK SEASONS
J43: WINDPEAKPCT Values *
B44: Summer Peak Ave. Wind Capacity Percentages and Total Unit Capacities | J44: Summer, Panhandle | K44: Summer, Coastal | L44: Summer, Other
B45: Top Twenty Peak Hours for Each year | J45: =SUMPRODUCT(C48:C57,D48:D57)/SUM(D48:D57) -> 0.29277598 | K45: =SUMPRODUCT(E48:E57,F48:F57)/SUM(F48:F57) -> 0.63294808 | L45: =SUMPRODUCT(G48:G57,H48:H57)/SUM(H48:H57) -> 0.1576587
B46: CDR Wind Region | C46: Panhandle | E46: Coastal | G46: Other
B47: Year | C47: Capacity Contribution Percentage | D47: Capacity (MW) | E47: Capacity Contribution Percentage | F47: Capacity (MW) | G47: Capacity Contribution Percentage | H47: Capacity (MW) | J47: * The methodology for calculating WINDPEAKPCT values is outlined in ERCOT Protocol Section 3.2.6.2.2. See: http://www.ercot.com/content/wcm/current_guides/53528/03-101819_Nodal.docx
B48: 2019 | C48: 0.34116316 | D48: 4197 | E48: 0.75046787 | F48: 2811.6 | G48: 0.2215483 | H48: 14949.9
B49: 2018 | C49: 0.25601249 | D49: 4197 | E49: 0.52912899 | F49: 2610.6 | G49: 0.17106233 | H49: 14289.9
B50: 2017 | C50: 0.24883959 | D50: 3171.2 | E50: 0.62928179 | F50: 2038.4 | G50: 0.20176401 | H50: 12241.2
...

Sheet WECC
A1: Released: November 2017
A2: Next Update: November 2018
A4: Table 3B.1. WECC monthly peak hour demand, by North American Electric Reliability Corporation Assesment Area,
A5: 1996-2016 actual, 2017-2018 projected
A6: megawatts
A8: WECC | B8: Year | C8: January | D8: February | E8: March | F8: April | G8: May | H8: June | I8: July | J8: August | K8: September | L8: October | M8: November | N8: December
A9: Actual | B9: 1996 | C9: 95306 | D9: 94878 | E9: 86486 | F9: 89912 | G9: 91930 | H9: 99203 | I9: 108739 | J9: 107790 | K9: 98006 | L9: 95427 | M9: 87466 | N9: 94331
B10: 1997 | C10: 95886 | D10: 89483 | E10: 89505 | F10: 88124 | G10: 99796 | H10: 98340 | I10: 104361 | J10: 110001 | K10: 105659 | L10: 95236 | M10: 89470 | N10: 93132
B11: 1998 | C11: 95102 | D11: 90267 | E11: 89009 | F11: 88242 | G11: 84051 | H11: 97617 | I11: 111830 | J11: 115921 | K11: 112705 | L11: 92543 | M11: 88524 | N11: 101822
B12: 1999 | C12: 91641 | D12: 91773 | E12: 87599 | F12: 87821 | G12: 91165 | H12: 105404 | I12: 113629 | J12: 109873 | K12: 102526 | L12: 96329 | M12: 90741 | N12: 96875
B13: 2000 | C13: 95673 | D13: 91627 | E13: 91044 | F13: 94250 | G13: 104053 | H13: 111600 | I13: 114472 | J13: 114602 | K13: 107797 | L13: 97398 | M13: 95483 | N13: 97324
B14: 2001 | C14: 96766 | D14: 93801 | E14: 87641 | F14: 90023 | G14: 100484 | H14: 105427 | I14: 108629 | J14: 109119 | K14: 101320 | L14: 97762 | M14: 91851 | N14: 95286
B15: 2002 | C15: 96555 | D15: 93195 | E15: 90041 | F15: 88714 | G15: 104110 | H15: 111108 | I15: 119074 | J15: 114763 | K15: 111475 | L15: 99967 | M15: 92834 | N15: 95951
B16: 2003 | C16: 92602 | D16: 93831 | E16: 91002 | F16: 89713 | G16: 110358 | H16: 112627 | I16: 122537 | J16: 119473 | K16: 113594 | L16: 103327 | M16: 94291 | N16: 99793
B17: 2004 | C17: 102049 | D17: 95546 | E17: 95191 | F17: 101654 | G17: 105503 | H17: 111143 | I17: 123136 | J17: 122922 | K17: 116784 | L17: 96429 | M17: 100001 | N17: 101541
B18: 2005 | C18: 102464 | D18: 96789 | E18: 90859 | F18: 90623 | G18: 106680 | H18: 115821 | I18: 130760 | J18: 125253 | K18: 113824 | L18: 101470 | M18: 100361 | N18: 107493
B19: 2006 | C19: 99571 | D19: 101154 | E19: 97101 | F19: 93098 | G19: 110713 | H19: 129742 | I19: 142096 | J19: 127749 | K19: 122420 | L19: 103797 | M19: 107335 | N19: 108617
B20: 2007 | C20: 107097 | D20: 101215 | E20: 98234 | F20: 98980 | G20: 107541 | H20: 126064 | I20: 137488 | J20: 139389 | K20: 128226 | L20: 99594 | M20: 100700 | N20: 109607
B21: 2008 | C21: 110395 | D21: 104200 | E21: 97743 | F21: 106357 | G21: 120959 | H21: 134781 | I21: 134052 | J21: 134829 | K21: 122386 | L21: 115877 | M21: 100056 | N21: 113605
... B29: 2016 | C29: 100315 | D29: 99421 | E29: 91447 | F29: 92268 | G29: 103561 | H29: 133247 | I29: 139431 | J29: 131343 | K29: 115093 | L29: 96692 | M29: 96181 | N29: 10400
A30: Projected | B30: 2017E | C30: 104737 | D30: 102180 | E30: 98101 | F30: 93343 | G30: 108475 | H30: 125996 | I30: 131791 | J30: 133410 | K30: 125256 | L30: 104962 | M30: 102551 | N30: 110022
B31: 2018E | C31: 105492 | D31: 102228 | E31: 97638 | F31: 94039 | G31: 109456 | H31: 128140 | I31: 132648 | J31: 132558 | K31: 127899 | L31: 106243 | M31: 102527 | N31: 110955

Sheet TRE
A1: Released: November 2017
A2: Next Update: November 2018
A4: Table 3B.1. TRE monthly peak hour demand, by North American Electric Reliability Corporation Assesment Area,
A5: 1996-2016 actual, 2017-2018 projected
A6: megawatts
A8: TRE | B8: Year | C8: January | D8: February | E8: March | F8: April | G8: May | H8: June | I8: July | J8: August | K8: September | L8: October | M8: November | N8: December
A9: Actual | B9: 1996 | C9: 36818 | D9: 37705 | E9: 34540 | F9: 35326 | G9: 43742 | H9: 46524 | I9: 47240 | J9: 46807 | K9: 41733 | L9: 34958 | M9: 34597 | N9: 39214
B10: 1997 | C10: 41280 | D10: 33120 | E10: 31783 | F10: 34216 | G10: 40857 | H10: 45687 | I10: 49705 | J10: 50468 | K10: 49005 | L10: 43533 | M10: 33624 | N10: 36458
B11: 1998 | C11: 35906 | D11: 33703 | E11: 36836 | F11: 35731 | G11: 48676 | H11: 52259 | I11: 53440 | J11: 54666 | K11: 51981 | L11: 46869 | M11: 32616 | N11: 40566
B12: 1999 | C12: 39537 | D12: 34343 | E12: 33383 | F12: 41080 | G12: 43529 | H12: 49628 | I12: 52925 | J12: 55529 | K12: 50447 | L12: 43706 | M12: 33615 | N12: 36685
B13: 2000 | C13: 39075 | D13: 34779 | E13: 38040 | F13: 40399 | G13: 50347 | H13: 49577 | I13: 55767 | J13: 57606 | K13: 57099 | L13: 47781 | M13: 35563 | N13: 44641
B14: 2001 | C14: 42995 | D14: 35091 | E14: 34090 | F14: 37017 | G14: 44606 | H14: 50918 | I14: 54846 | J14: 55201 | K14: 50073 | L14: 40796 | M14: 41608 | N14: 36557
B15: 2002 | C15: 43901 | D15: 43837 | E15: 43964 | F15: 49064 | G15: 49018 | H15: 51882 | I15: 54891 | J15: 56248 | K15: 51556 | L15: 49105 | M15: 35901 | N15: 40650
B16: 2003 | C16: 45433 | D16: 43498 | E16: 37554 | F16: 40579 | G16: 52909 | H16: 53637 | I16: 56251 | J16: 59996 | K16: 49502 | L16: 42651 | M16: 38608 | N16: 40782
B17: 2004 | C17: 42698 | D17: 42301 | E17: 34321 | F17: 39131 | G17: 48702 | H17: 54061 | I17: 56489 | J17: 58531 | K17: 55179 | L17: 47714 | M17: 37599 | N17: 44010
B18: 2005 | C18: 40966 | D18: 41095 | E18: 36115 | F18: 41219 | G18: 51947 | H18: 58140 | I18: 57319 | J18: 60210 | K18: 59524 | L18: 52107 | M18: 42470 | N18: 47948
B19: 2006 | C19: 38604 | D19: 43210 | E19: 38257 | F19: 51800 | G19: 54175 | H19: 57887 | I19: 61660 | J19: 62339 | K19: 56603 | L19: 50890 | M19: 45143 | N19: 46896
B20: 2007 | C20: 50404 | D20: 50408 | E20: 38827 | F20: 41710 | G20: 49222 | H20: 56427 | I20: 56754 | J20: 62188 | K20: 55091 | L20: 54102 | M20: 39993 | N20: 44443
B21: 2008 | C21: 46099 | D21: 45321.168 | E21: 42412.086 | F21: 45872.209 | G21: 56343.9 | H21: 59642.121 | I21: 61119.607 | J21: 62174.377 | K21: 56342.604 | L21: 46574.727 | M21: 38746.451 | N21: 47805.655
... B29: 2016 | C29: 49262.558 | D29: 47416.492 | E29: 43347.187 | F29: 50932.083 | G29: 57223.827 | H29: 64896.26 | I29: 67468.932 | J29: 71110.104 | K29: 66948.566 | L29: 59864.268 | M29: 50012.351 | N29: 57932.433
A30: Projected | B30: 2017E | C30: 54417.089 | D30: 52494.977 | E30: 46877.756 | F30: 51622.356 | G30: 58907.858 | H30: 66915.332 | I30: 68657.3 | J30: 72933.55 | K30: 64448.591 | L30: 56096.829 | M30: 45791.007 | N30: 52669.431
B31: 2018E | C31: 55003.088 | D31: 53084.39 | E31: 47485.515 | F31: 52357.575 | G31: 59695.215 | H31: 67905.306 | I31: 69666.623 | J31: 74149.387 | K31: 65482.963 | L31: 57090.494 | M31: 46784.411 | N31: 53494.896

Sheet MISO
A1: Released: November 2017
A2: Next Update: November 2018
A4: Table 3B.1. MISO monthly peak hour demand, by North American Electric Reliability Corporation Assesment Area,
A5: 1996-2016 actual, 2017-2018 projected
A6: megawatts
A8: MISO | B8: Year | C8: January | D8: February | E8: March | F8: April | G8: May | H8: June | I8: July | J8: August | K8: September | L8: October | M8: November | N8: December
A9: Actual | B9: 1996 | C9: NA | D9: NA | E9: NA | F9: NA | G9: NA | H9: NA | I9: NA | J9: NA | K9: NA | L9: NA | M9: NA | N9: NA
B10: 1997 | C10: NA | D10: NA | E10: NA | F10: NA | G10: NA | H10: NA | I10: NA | J10: NA | K10: NA | L10: NA | M10: NA | N10: NA
B11: 1998 | C11: NA | D11: NA | E11: NA | F11: NA | G11: NA | H11: NA | I11: NA | J11: NA | K11: NA | L11: NA | M11: NA | N11: NA
B12: 1999 | C12: NA | D12: NA | E12: NA | F12: NA | G12: NA | H12: NA | I12: NA | J12: NA | K12: NA | L12: NA | M12: NA | N12: NA
B13: 2000 | C13: NA | D13: NA | E13: NA | F13: NA | G13: NA | H13: NA | I13: NA | J13: NA | K13: NA | L13: NA | M13: NA | N13: NA
B14: 2001 | C14: NA | D14: NA | E14: NA | F14: NA | G14: NA | H14: NA | I14: NA | J14: NA | K14: NA | L14: NA | M14: NA | N14: NA
B15: 2002 | C15: NA | D15: NA | E15: NA | F15: NA | G15: NA | H15: NA | I15: NA | J15: NA | K15: NA | L15: NA | M15: NA | N15: NA
B16: 2003 | C16: NA | D16: NA | E16: NA | F16: NA | G16: NA | H16: NA | I16: NA | J16: NA | K16: NA | L16: NA | M16: NA | N16: NA
B17: 2004 | C17: NA | D17: NA | E17: NA | F17: NA | G17: NA | H17: NA | I17: NA | J17: NA | K17: NA | L17: NA | M17: NA | N17: NA
B18: 2005 | C18: NA | D18: NA | E18: NA | F18: NA | G18: NA | H18: NA | I18: NA | J18: NA | K18: NA | L18: NA | M18: NA | N18: NA
B19: 2006 | C19: NA | D19: NA | E19: NA | F19: NA | G19: NA | H19: NA | I19: NA | J19: NA | K19: NA | L19: NA | M19: NA | N19: NA
B20: 2007 | C20: NA | D20: NA | E20: NA | F20: NA | G20: NA | H20: NA | I20: NA | J20: NA | K20: NA | L20: NA | M20: NA | N20: NA
B21: 2008 | C21: NA | D21: NA | E21: NA | F21: NA | G21: NA | H21: NA | I21: NA | J21: NA | K21: NA | L21: NA | M21: NA | N21: NA
B22: 2009 | C22: NA | D22: NA | E22: NA | F22: NA | G22: NA | H22: NA | I22: NA | J22: NA | K22: NA | L22: NA | M22: NA | N22: NA
B23: 2010 | C23: 85264.71 | D23: 81835.57 | E23: 74562.29 | F23: 69824.01 | G23: 92068.42 | H23: 98927.17 | I23: 104024.22 | J23: 108346.11 | K23: 93747.63 | L23: 73309.84 | M23: 79454.15 | N23: 90848.02
B24: 2011 | C24: 85965.69 | D24: 87676.94 | E24: 76964.05 | F24: 68204.943 | G24: 75208.682 | H24: 91832.35 | I24: 98067.621 | J24: 96870.964 | K24: 87569.553 | L24: 71648.493 | M24: 72383.362 | N24: 79051.785
B25: 2012 | C25: 70600 | D25: 67013 | E25: 63375 | F25: 58449 | G25: 70656 | H25: 92955 | I25: 96769 | J25: 89327 | K25: 83877 | L25: 61312 | M25: 66201 | N25: 69270
B26: 2013 | C26: 93797.6 | D26: 92559.6 | E26: 85284.1 | F26: 79153.6 | G26: 98121.9 | H26: 110585.9 | I26: 121124.3 | J26: 117842.9 | K26: 115803.6 | L26: 89798.7 | M26: 90021 | N26: 95803.3
B27: 2014 | C27: 107927.3 | D27: 101304.4 | E27: 96058.7 | F27: 80236 | G27: 92600.3 | H27: 109196.2 | I27: 113506.9 | J27: 113429.2 | K27: 109527.4 | L27: 87007 | M27: 95703 | N27: 91339
B28: 2015 | C28: 104723 | D28: 99159 | E28: 95741 | F28: 78291 | G28: 92464 | H28: 106054 | I28: 118325 | J28: 113012 | K28: 111857 | L28: 83186 | M28: 82367 | N28: 85296
B29: 2016 | C29: 95920 | D29: 91654 | E29: 81073 | F29: 78230 | G29: 93952 | H29: 111350 | I29: 119506 | J29: 118413 | K29: 113557 | L29: 89127 | M29: 80912 | N29: 99054
A30: Projected | B30: 2017E | C30: 103867 | D30: 95220.8 | E30: 92406.4 | F30: 86298.6 | G30: 98473.7 | H30: 116607.8 | I30: 125000.3 | J30: 124809.9 | K30: 111790.7 | L30: 91213.6 | M30: 90038.6 | N30: 97900.5
B31: 2018E | C31: 103730.7 | D31: 95341.4 | E31: 91310.6 | F31: 85249.8 | G31: 95920.1 | H31: 117056.7 | I31: 125313.6 | J31: 125568.1 | K31: 112646.4 | L31: 91984.3 | M31: 90780.5 | N31: 98608.8

Sheet SPP
A1: Released: November 2017
A2: Next Update: November 2018
A4: Table 3B.1. SPP monthly peak hour demand, by North American Electric Reliability Corporation Assesment Area,
A5: 1996-2016 actual, 2017-2018 projected
A6: megawatts
A8: SPP | B8: Year | C8: January | D8: February | E8: March | F8: April | G8: May | H8: June | I8: July | J8: August | K8: September | L8: October | M8: November | N8: December
A9: Actual | B9: 1996 | C9: 46801 | D9: 46506 | E9: 44043 | F9: 39428 | G9: 52072 | H9: 56569 | I9: 59826 | J9: 57907 | K9: 52017 | L9: 41352 | M9: 42117 | N9: 48274
B10: 1997 | C10: 26931 | D10: 23739 | E10: 22386 | F10: 22283 | G10: 24746 | H10: 32950 | I10: 36267 | J10: 35024 | K10: 33793 | L10: 28435 | M10: 24029 | N10: 25020
B11: 1998 | C11: 24313 | D11: 23137 | E11: 24878 | F11: 22119 | G11: 32030 | H11: 36086 | I11: 37383 | J11: 36976 | K11: 35910 | L11: 25231 | M11: 22274 | N11: 26725
B12: 1999 | C12: 26757 | D12: 23604 | E12: 23086 | F12: 23648 | G12: 25872 | H12: 32783 | I12: 37958 | J12: 38609 | K12: 34692 | L12: 25745 | M12: 22773 | N12: 25415
B13: 2000 | C13: 26415 | D13: 25463 | E13: 23516 | F13: 25516 | G13: 35188 | H13: 34162 | I13: 38864 | J13: 40101 | K13: 39246 | L13: 30910 | M13: 25942 | N13: 30137
B14: 2001 | C14: 28039 | D14: 26733 | E14: 24707 | F14: 26240 | G14: 32043 | H14: 35636 | I14: 40063 | J14: 39782 | K14: 34312 | L14: 26688 | M14: 26949 | N14: 25951
B15: 2002 | C15: 28485 | D15: 28191 | E15: 27833 | F15: 28356 | G15: 32514 | H15: 36228 | I15: 39125 | J15: 39571 | K15: 37659 | L15: 31961 | M15: 25788 | N15: 27710
B16: 2003 | C16: 28850 | D16: 27922 | E16: 26026 | F16: 26518 | G16: 32880 | H16: 35810 | I16: 39133 | J16: 40214 | K16: 32876 | L16: 26372 | M16: 25204 | N16: 27259
B17: 2004 | C17: 29010 | D17: 27454 | E17: 23566 | F17: 24583 | G17: 32878 | H17: 36137 | I17: 39893 | J17: 39734 | K17: 36117 | L17: 27158 | M17: 26603 | N17: 29782
B18: 2005 | C18: 29072 | D18: 27128 | E18: 25247 | F18: 25656 | G18: 34261 | H18: 39437 | I18: 41306 | J18: 40771 | K18: 37772 | L18: 33042 | M18: 27333 | N18: 31764
B19: 2006 | C19: 26864 | D19: 28402 | E19: 25548 | F19: 31231 | G19: 36115 | H19: 37754 | I19: 42556 | J19: 42405 | K19: 33342 | L19: 33653 | M19: 29699 | N19: 30331
B20: 2007 | C20: 30141 | D20: 31028 | E20: 25629 | F20: 26746 | G20: 31495 | H20: 36775 | I20: 38965 | J20: 43165 | K20: 36887 | L20: 33537 | M20: 26610 | N20: 29560
B21: 2008 | C21: 31294 | D21: 30140 | E21: 28268 | F21: 27213 | G21: 33650 | H21: 38629 | I21: 41914 | J21: 43476 | K21: 34823 | L21: 27993 | M21: 27133 | N21: 32361
... B29: 2016 | C29: 38748.23 | D29: 36562.031 | E29: 32928.927 | F29: 32909.973 | G29: 37424.912 | H29: 49559.558 | I29: 51802.681 | J29: 51882.931 | K29: 45676.56 | L29: 38354.744 | M29: 34484.872 | N29: 41533.675
A30: Projected | B30: 2017E | C30: 40786.321 | D30: 39769.572 | E30: 35922.737 | F30: 34670.573 | G30: 39868.457 | H30: 47893.182 | I30: 52403.478 | J30: 52103.814 | K30: 46244.453 | L30: 38021.89 | M30: 35875.684 | N30: 39984.583
B31: 2018E | C31: 41215.177 | D31: 40329.926 | E31: 35913.811 | F31: 34630.61 | G31: 39763.159 | H31: 48300.956 | I31: 52553.746 | J31: 52486.321 | K31: 46597.653 | L31: 38299.63 | M31: 36194.446 | N31: 40855.47

Sheet PJM
A1: Released: November 2017
A2: Next Update: November 2018
A4: Table 3B.1. PJM monthly peak hour demand, by North American Electric Reliability Corporation Assesment Area,
A5: 1996-2016 actual, 2017-2018 projected
A6: megawatts
A8: PJM | B8: Year | C8: January | D8: February | E8: March | F8: April | G8: May | H8: June | I8: July | J8: August | K8: September | L8: October | M8: November | N8: December
A9: Actual | B9: 1996 | C9: NA | D9: NA | E9: NA | F9: NA | G9: NA | H9: NA | I9: NA | J9: NA | K9: NA | L9: NA | M9: NA | N9: NA
B10: 1997 | C10: NA | D10: NA | E10: NA | F10: NA | G10: NA | H10: NA | I10: NA | J10: NA | K10: NA | L10: NA | M10: NA | N10: NA
B11: 1998 | C11: NA | D11: NA | E11: NA | F11: NA | G11: NA | H11: NA | I11: NA | J11: NA | K11: NA | L11: NA | M11: NA | N11: NA
B12: 1999 | C12: NA | D12: NA | E12: NA | F12: NA | G12: NA | H12: NA | I12: NA | J12: NA | K12: NA | L12: NA | M12: NA | N12: NA
B13: 2000 | C13: NA | D13: NA | E13: NA | F13: NA | G13: NA | H13: NA | I13: NA | J13: NA | K13: NA | L13: NA | M13: NA | N13: NA
B14: 2001 | C14: NA | D14: NA | E14: NA | F14: NA | G14: NA | H14: NA | I14: NA | J14: NA | K14: NA | L14: NA | M14: NA | N14: NA
B15: 2002 | C15: NA | D15: NA | E15: NA | F15: NA | G15: NA | H15: NA | I15: NA | J15: NA | K15: NA | L15: NA | M15: NA | N15: NA
B16: 2003 | C16: NA | D16: NA | E16: NA | F16: NA | G16: NA | H16: NA | I16: NA | J16: NA | K16: NA | L16: NA | M16: NA | N16: NA
B17: 2004 | C17: NA | D17: NA | E17: NA | F17: NA | G17: NA | H17: NA | I17: NA | J17: NA | K17: NA | L17: NA | M17: NA | N17: NA
B18: 2005 | C18: NA | D18: NA | E18: NA | F18: NA | G18: NA | H18: NA | I18: NA | J18: NA | K18: NA | L18: NA | M18: NA | N18: NA
B19: 2006 | C19: NA | D19: NA | E19: NA | F19: NA | G19: NA | H19: NA | I19: NA | J19: NA | K19: NA | L19: NA | M19: NA | N19: NA
B20: 2007 | C20: NA | D20: NA | E20: NA | F20: NA | G20: NA | H20: NA | I20: NA | J20: NA | K20: NA | L20: NA | M20: NA | N20: NA
B21: 2008 | C21: NA | D21: NA | E21: NA | F21: NA | G21: NA | H21: NA | I21: NA | J21: NA | K21: NA | L21: NA | M21: NA | N21: NA
B22: 2009 | C22: NA | D22: NA | E22: NA | F22: NA | G22: NA | H22: NA | I22: NA | J22: NA | K22: NA | L22: NA | M22: NA | N22: NA
B23: 2010 | C23: 109179.21 | D23: 104915.35 | E23: 95014.774 | F23: 88409.15 | G23: 110783.37 | H23: 126201.95 | I23: 136465.12 | J23: 131946.46 | K23: 127681.9 | L23: 85652.149 | M23: 90313.391 | N23: 115535
B24: 2011 | C24: 113912 | D24: 109621 | E24: 99956 | F24: 92104 | G24: 103609 | H24: 139967 | I24: 148941 | J24: 143584 | K24: 126463 | L24: 101712 | M24: 108310 | N24: 122418
B25: 2012 | C25: 122565.44 | D25: 113997.64 | E25: 107528.11 | F25: 97821.804 | G25: 130557.66 | H25: 147915.07 | I25: 154338.73 | J25: 144486.46 | K25: 129958.53 | L25: 98761.609 | M25: 107454.81 | N25: 109947.9
B26: 2013 | C26: 126725 | D26: 118740 | E26: 109671 | F26: 101046 | G26: 129053 | H26: 139781 | I26: 157509 | J26: 137625 | K26: 143461 | L26: 108826 | M26: 114699 | N26: 124072
B27: 2014 | C27: 140510.23 | D27: 129690.52 | E27: 126638.86 | F27: 99179.552 | G27: 119741.91 | H27: 141677.93 | I27: 139379.87 | J27: 133390.98 | K27: 138157.14 | L27: 95919.772 | M27: 120847.9 | N27: 114047.33
B28: 2015 | C28: 136197 | D28: 143129 | E28: 125701 | F28: 96382 | G28: 120840 | H28: 137287 | I28: 143633 | J28: 139649 | K28: 141209 | L28: 94824 | M28: 104505 | N28: 104494
B29: 2016 | C29: 129775 | D29: 121307 | E29: 106497 | F29: 99868 | G29: 121539 | H29: 134752 | I29: 150826 | J29: 152177 | K29: 142092 | L29: 102277 | M29: 105171 | N29: 131021
A30: Projected | B30: 2017E | C30: 131391 | D30: 125630 | E30: 115099 | F30: 105560 | G30: 120074 | H30: 144469 | I30: 152999 | J30: 148808 | K30: 129257 | L30: 107258 | M30: 111523 | N30: 125798
B31: 2018E | C31: 132652 | D31: 126874 | E31: 115332 | F31: 110453 | G31: 121060 | H31: 145187 | I31: 153951 | J31: 149526 | K31: 129112 | L31: 110657 | M31: 112483 | N31: 127154

Sheet NPCC
A1: Released: November 2017
A2: Next Update: November 2018
A4: Table 3B.1. NPCC monthly peak hour demand, by North American Electric Reliability Corporation Assesment Area,
A5: 1996-2016 actual, 2017-2018 projected
A6: megawatts
A8: NPCC | B8: Year | C8: January | D8: February | E8: March | F8: April | G8: May | H8: June | I8: July | J8: August | K8: September | L8: October | M8: November | N8: December
A9: Actual | B9: 1996 | C9: 41680 | D9: 41977 | E9: 39414 | F9: 35313 | G9: 41013 | H9: 41893 | I9: 44773 | J9: 44663 | K9: 43321 | L9: 36278 | M9: 38992 | N9: 39710
B10: 1997 | C10: 41208 | D10: 38891 | E10: 37662 | F10: 35284 | G10: 34101 | H10: 46477 | I10: 49269 | J10: 43964 | K10: 42487 | L10: 37597 | M10: 39602 | N10: 41178
B11: 1998 | C11: 40009 | D11: 39624 | E11: 39652 | F11: 35382 | G11: 40210 | H11: 47342 | I11: 49566 | J11: 47514 | K11: 42358 | L11: 36947 | M11: 38738 | N11: 41728
B12: 1999 | C12: 44199 | D12: 41263 | E12: 39883 | F12: 34260 | G12: 35911 | H12: 50127 | I12: 52855 | J12: 47762 | K12: 45913 | L12: 37120 | M12: 41314 | N12: 42166
B13: 2000 | C13: 45227 | D13: 42692 | E13: 38729 | F13: 36124 | G13: 44550 | H13: 50057 | I13: 46310 | J13: 49850 | K13: 48266 | L13: 39300 | M13: 41036 | N13: 43852
B14: 2001 | C14: 43553 | D14: 41919 | E14: 40636 | F14: 37191 | G14: 42368 | H14: 50289 | I14: 53569 | J14: 55949 | K14: 45703 | L14: 38398 | M14: 39576 | N14: 42540
B15: 2002 | C15: 42039 | D15: 41544 | E15: 39906 | F15: 42163 | G15: 41008 | H15: 51873 | I15: 55444 | J15: 55944 | K15: 49324 | L15: 43293 | M15: 40696 | N15: 44793
B16: 2003 | C16: 45987 | D16: 43800 | E16: 43249 | F16: 38921 | G16: 36648 | H16: 54827 | I16: 53509 | J16: 53540 | K16: 43123 | L16: 39225 | M16: 40197 | N16: 44257
B17: 2004 | C17: 66215 | D17: 62361 | E17: 58055 | F17: 54300 | G17: 64042 | H17: 76529 | I17: 82615 | J17: 79138 | K17: 73418 | L17: 56870 | M17: 60680 | N17: 67224
B18: 2005 | C18: 47041 | D18: 42949 | E18: 43487 | F18: 37399 | G18: 37543 | H18: 55720 | I18: 58960 | J18: 58009 | K18: 50704 | L18: 41854 | M18: 41875 | N18: 46828
B19: 2006 | C19: 43661 | D19: 43611 | E19: 42532 | F19: 37331 | G19: 46113 | H19: 52000 | I19: 59953 | J19: 63241 | K19: 43207 | L19: 40157 | M19: 41149 | N19: 44570
B20: 2007 | C20: 45002 | D20: 46697 | E20: 45901 | F20: 38936 | G20: 46586 | H20: 57272 | I20: 56073 | J20: 58314 | K20: 51463 | L20: 45066 | M20: 41766 | N20: 46024
B21: 2008 | C21: 46803 | D21: 44882 | E21: 40421 | F21: 37426 | G21: 40348 | H21: 58543 | I21: 55919 | J21: 50393 | K21: 50957 | L21: 39251 | M21: 42111 | N21: 45695
... B29: 2016 | C29: 42768.4 | D29: 42862.3 | E29: 38575.2 | F29: 37136.1 | G29: 44089.6 | H29: 46251.5 | I29: 55603.3 | J29: 57671.5 | K29: 52778.8 | L29: 37440.6 | M29: 39129.5 | N29: 43745
A30: Projected | B30: 2017E | C30: 45756 | D30: 43291 | E30: 41875 | F30: 36109 | G30: 43524 | H30: 53031 | I30: 59660 | J30: 58200 | K30: 49570 | L30: 38777 | M30: 39883 | N30: 45002
B31: 2018E | C31: 45562 | D31: 43238 | E31: 41804 | F31: 35961 | G31: 43285 | H31: 52870 | I31: 59536 | J31: 58081 | K31: 49394 | L31: 38577 | M31: 39713 | N31: 44744

Sheet EIA Form 411
A1: Interconnection | B1: NERC Regional Assesment Area
C2: Actual | AD2: Projected
C3: 1990 | D3: 1991 | E3: 1992 | F3: 1993 | G3: 1994 | H3: 1995 | I3: 1996 | J3: 1997 | K3: 1998 | L3: 1999 | M3: 2000 | N3: 2001 | O3: 2002 | P3: 2003 | Q3: 2004 | R3: 2005 | S3: 2006 | T3: 2007 | U3: 2008 | V3: 2009 | W3: 2010 | X3: 2011 | Y3: 2012 | Z3: 2013 | AA3: 2014 | AB3: 2015 | AC3: 2016 | AD3: 2017E | AE3: 2018E | AF3: 2019E | AG3: 2020E | AH3: 2021E | AI3: 2022E | AJ3: 2023E | AK3: 2024E | AL3: 2025E | AM3: 2026E | AN3: 2027E
A4: Eastern Interconnection | B4: FRCC | C4: 142502 | D4: 146903 | E4: 147464 | F4: 153468 | G4: 159861 | H4: 169021 | I4: 173377 | J4: 175557 | K4: 188384 | L4: 188598 | M4: 196561 | N4: 200134 | O4: 211116 | P4: 219021 | Q4: 220335 | R4: 226544 | S4: 230115 | T4: 232405 | U4: 226874 | V4: 225966 | W4: 233034 | X4: 224064 | Y4: 220943 | Z4: 221534 | AA4: 224646 | AB4: 234489 | AC4: 234041 | AD4: 230867 | AE4: 233407 | AF4: 235517 | AG4: 238021 | AH4: 239553 | AI4: 241812 | AJ4: 243938 | AK4: 246540 | AL4: 248440 | AM4: 250948 | AN4: 250948
B5: NPCC | C5: 250681 | D5: 253701 | E5: 252256 | F5: 257447 | G5: 259947 | H5: 261235 | I5: 263125 | J5: 264464 | K5: 268309 | L5: 277902 | M5: 281518 | N5: 282670 | O5: 286199 | P5: 288791 | Q5: 292724.5 | R5: 303607 | S5: 294319 | T5: 301766 | U5: 297362 | V5: 285624.67 | W5: 294276 | X5: 292481.71 | Y5: 290914 | Z5: 292882 | AA5: 287160 | AB5: 286280 | AC5: 285179 | AD5: 283820 | AE5: 284422 | AF5: 283141 | AG5: 281192 | AH5: 278832 | AI5: 277303 | AJ5: 276292 | AK5: 275484 | AL5: 274920 | AM5: 274600 | AN5: 274420
B6: Balance of Eastern Region | C6: 1725276 | D6: 1774108 | E6: 1766746 | F6: 1871168 | G6: 1907338 | H6: 1999873 | I6: 2059485 | J6: 2062452 | K6: 2112728 | L6: 2147860 | M6: 2210739 | N6: 2203509 | O6: 2301321 | P6: 2255233 | Q6: 2313180 | R6: 2385460.9 | S6: 2361721 | T6: 2432474.6 | U6: 2406730 | V6: 2293617.3 | W6: 2456553.3 | X6: 2401810.2 | Y6: =SUM(Y7:Y16) -> 2391745 | Z6: =SUM(Z7:Z16) -> 2394268 | AA6: =SUM(AA7:AA16) -> 2387853 | AB6: =SUM(AB7:AB16) -> 2370799.1 | AC6: =SUM(AC7:AC16) -> 2381793.9 | AD6: =SUM(AD7:AD16) -> 2437101.8 | AE6: =SUM(AE7:AE16) -> 2486517.9 | AF6: =SUM(AF7:AF16) -> 2494678.2 | ... AN6: =SUM(AN7:AN16) -> 2596540.3
B7: ECAR | C7: 442507 | D7: 450586 | E7: 450853 | F7: 476644 | G7: 487489 | H7: 521247 | I7: 532747 | J7: 524414 | K7: 535015 | L7: 547846 | M7: 545958 | N7: 546167 | O7: 567897 | P7: 545109 | Q7: 553236 | R7: NA | S7: NA | T7: NA | U7: NA | V7: NA | W7: NA | X7: NA | Y7: NA | Z7: NA | AA7: NA | AB7: NA | AC7: NA | AD7: NA | AE7: NA | AF7: NA | AG7: NA | AH7: NA | AI7: NA | AJ7: NA | AK7: NA | AL7: NA | AM7: NA | AN7: NA
B8: MAAC | C8: 221099 | D8: 228588 | E8: 226154 | F8: 235980 | G8: 238379 | H8: 243043 | I8: 243328 | J8: 243967 | K8: 248806 | L8: 255741 | M8: 262320 | N8: 263841 | O8: 273907 | P8: 276600 | Q8: 283646 | R8: NA | S8: NA | T8: NA | U8: NA | V8: NA | W8: NA | X8: NA | Y8: NA | Z8: NA | AA8: NA | AB8: NA | AC8: NA | AD8: NA | AE8: NA | AF8: NA | AG8: NA | AH8: NA | AI8: NA | AJ8: NA | AK8: NA | AL8: NA | AM8: NA | AN8: NA
B9: MAIN | C9: 197326 | D9: 205880 | E9: 200250 | F9: 208340 | G9: 213803 | H9: 224380 | I9: 234300 | J9: 236143 | K9: 244073 | L9: 243278 | M9: 259608 | N9: 271053 | O9: 279264 | P9: 267068 | Q9: 274760 | R9: NA | S9: NA | T9: NA | U9: NA | V9: NA | W9: NA | X9: NA | Y9: NA | Z9: NA | AA9: NA | AB9: NA | AC9: NA | AD9: NA | AE9: NA | AF9: NA | AG9: NA | AH9: NA | AI9: NA | AJ9: NA | AK9: NA | AL9: NA | AM9: NA | AN9: NA
B10: MAPP | C10: NA | D10: NA | E10: NA | F10: NA | G10: NA | H10: NA | I10: NA | J10: NA | K10: NA | L10: NA | M10: NA | N10: NA | O10: NA | P10: NA | Q10: NA | R10: NA | S10: NA | T10: NA | U10: NA | V10: NA | W10: 30690.612 | X10: 29232.665 | Y10: 29362 | Z10: 29798 | AA10: 31756 | AB10: NA | AC10: NA | AD10: NA | AE10: NA | AF10: NA | AG10: NA | AH10: NA | AI10: NA | AJ10: NA | AK10: NA | AL10: NA | AM10: NA | AN10: NA
B11: MISO | C11: NA | D11: NA | E11: NA | F11: NA | G11: NA | H11: NA | I11: NA | J11: NA | K11: NA | L11: NA | M11: NA | N11: NA | O11: NA | P11: NA | Q11: NA | R11: NA | S11: NA | T11: NA | U11: NA | V11: NA | W11: 585273.92 | X11: 521691.61 | Y11: 497906 | Z11: 662636 | AA11: 641290 | AB11: 659676.8 | AC11: 660862 | AD11: 693350.58 | AE11: 727495.09 | AF11: 730209.6 | AG11: 734426.8 | AH11: 737476.7 | AI11: 743245.1 | AJ11: 748127.3 | AK11: 751630.1 | AL11: 756057.6 | AM11: 760001.2 | AN11: 763944.8
B12: MRO | C12: 127102 | D12: 129826 | E12: 126881 | F12: 131112 | G12: 136498 | H12: 143447 | I12: 145479 | J12: 151661 | K12: 155194 | L12: 152350 | M12: 145981 | N12: 144893 | O12: 150058 | P12: 153918 | Q12: 152975 | R12: 216632.62 | S12: 222748 | T12: 217601.6 | U12: 227536 | V12: 213797.03 | W12: NA | X12: NA | Y12: NA | Z12: NA | AA12: NA | AB12: NA | AC12: NA | AD12: NA | AE12: NA | AF12: NA | AG12: NA | AH12: NA | AI12: NA | AJ12: NA | AK12: NA | AL12: NA | AM12: NA | AN12: NA
B13: PJM | C13: NA | D13: NA | E13: NA | F13: NA | G13: NA | H13: NA | I13: NA | J13: NA | K13: NA | L13: NA | M13: NA | N13: NA | O13: NA | P13: NA | Q13: NA | R13: NA | S13: NA | T13: NA | U13: NA | V13: NA | W13: 712730.91 | X13: 739754.49 | Y13: 781247 | Z13: 791151 | AA13: 797461 | AB13: 792566 | AC13: 792313 | AD13: 814868 | AE13: 821638 | AF13: 823890 | AG13: 822831 | AH13: 820415 | AI13: 821341 | AJ13: 822626 | AK13: 827522 | AL13: 831502 | AM13: 835137 | AN13: 841099
B14: RFC | C14: NA | D14: NA | E14: NA | F14: NA | G14: NA | H14: NA | I14: NA | J14: NA | K14: NA | L14: NA | M14: NA | N14: NA | O14: NA | P14: NA | Q14: NA | R14: 1005226 | S14: 926279 | T14: 954700 | U14: 936201 | V14: 880377.1 | W14: NA | X14: NA | Y14: NA | Z14: NA | AA14: NA | AB14: NA | AC14: NA | AD14: NA | AE14: NA | AF14: NA | AG14: NA | AH14: NA | AI14: NA | AJ14: NA | AK14: NA | AL14: NA | AM14: NA | AN14: NA
B15: SERC | C15: 485205 | D15: 501794 | E15: 506140 | F15: 538339 | G15: 544945 | H15: 572587 | I15: 596940 | J15: 730248 | K15: 746538 | L15: 768408 | M15: 803211 | N15: 787139 | O15: 835319 | P15: 826964 | Q15: 856734 | R15: 962054.23 | S15: 1011173 | T15: 1049298 | U15: 1035390 | V15: 997142 | W15: 870367 | X15: 852843.06 | Y15: 824640 | Z15: 661124 | AA15: 674054 | AB15: 668126 | AC15: 672720 | AD15: 673339 | AE15: 677048 | AF15: 681238 | AG15: 685684 | AH15: 689388 | AI15: 693376 | AJ15: 698595 | AK15: 703979 | AL15: 708819 | AM15: 714335 | AN15: 720420
B16: SPP | C16: 252037 | D16: 257434 | E16: 256468 | F16: 280753 | G16: 286224 | H16: 295169 | I16: 306691 | J16: 176019 | K16: 183102 | L16: 180237 | M16: 193661 | N16: 190416 | O16: 194876 | P16: 185574 | Q16: 191829 | R16: 201548 | S16: 201521 | T16: 210875 | U16: 207603 | V16: 202301.13 | W16: 257490.87 | X16: 258288.33 | Y16: 258590 | Z16: 249559 | AA16: 243292 | AB16: 250430.31 | AC16: 255898.87 | AD16: 255544.25 | AE16: 260336.78 | AF16: 259340.6 | AG16: 259625.2 | AH16: 260791.2 | AI16: 264592.9 | AJ16: 265897.2 | AK16: 267367.3 | AL16: 268763.2 | AM16: 269850.2 | AN16: 271076.5
A17: ERCOT | B17: TRE | C17: 209789 | D17: 211568 | E17: 210699 | F17: 221901 | G17: 225098 | H17: 231440 | I17: 243456 | J17: 251840 | K17: 267970 | L17: 268622 | M17: 286313 | N17: 278226 | O17: 280269 | P17: 283868 | Q17: 289146 | R17: 299225 | S17: 305672 | T17: 307064 | U17: 312401.08 | V17: 308277.76 | W17: 319097.4 | X17: 335000.18 | Y17: 324860 | Z17: 331624 | AA17: 340033 | AB17: 347617.44 | AC17: 375889.79 | AD17: 356428.37 | AE17: 363665.2 | AF17: 373761.96 | AG17: 380660.73 | AH17: 386550.85 | AI17: 392714.56 | AJ17: 398843.55 | AK17: 405017.83 | AL17: 411040.99 | AM17: 417426.76 | AN17: 425775.29
A18: Western Interconnection | B18: WECC | C18: 558248 | D18: 555389 | E18: 565745 | F18: 569319 | G18: 586192 | H18: 586167 | I18: 611650 | J18: 620629 | K18: 625791 | L18: 635503 | M18: 663913 | N18: 638746 | O18: 666696 | P18: 664754 | Q18: 682053 | R18: 685624 | S18: 720087 | T18: 739018 | U18: 745691 | V18: 718694 | W18: 713176.76 | X18: 727793 | Y18: 726862 | Z18: 737458 | AA18: 733664 | AB18: 728896 | AC18: 737155 | AD18: 731132 | AE18: 732688 | AF18: 737745 | AG18: 741668 | AH18: 746071 | AI18: 751940 | AJ18: 757807 | AK18: 763228 | AL18: 767234 | AM18: 771575 | AN18: 775800
A19: All Interconnections | B19: Contiguous U.S. | C19: 2886496 | D19: 2941669 | E19: 2942910 | F19: 3073303 | G19: 3138436 | H19: 3247736 | I19: 3351093 | J19: 3374942 | K19: 3463182 | L19: 3518485 | M19: 3639044 | N19: 3603285 | O19: 3745601 | P19: 3711667 | Q19: 3797438.5 | R19: 3900460.9 | S19: 3911914 | T19: 4012727.6 | U19: 3989058.1 | V19: 3832179.7 | W19: 4016137.5 | X19: 3981149 | Y19: =Y4+Y5+Y6+Y17+Y18 -> 3955324 | Z19: =Z4+Z5+Z6+Z17+Z18 -> 3977766 | AA19: =AA4+AA5+AA6+AA17+AA18 -> 3973356 | AB19: =AB4+AB5+AB6+AB17+AB18 -> 3968081.5 | AC19: =AC4+AC5+AC6+AC17+AC18 -> 4014058.7 | AD19: =AD4+AD5+AD6+AD17+AD18 -> 4039349.2 | AE19: =AE4+AE5+AE6+AE17+AE18 -> 4100700.1 | AF19: =AF4+AF5+AF6+AF17+AF18 -> 4124843.2 | ... AN19: =AN4+AN5+AN6+AN17+AN18 -> 4323483.6
A20: Notes: • NERC region and reliability assessment area maps are provided on EIA's Electricity Reliability web page: http://www.eia.gov/electricity/data/eia411/
A21: • Projected data are updated annually.
A22: • Peak load represents an hour of a day during the associated peak period.
A23: • The Summer peak period begins on June1 and extends through September 30. • The Winter peak period begins October 1 and extends through May 31.
A24: • Historically the MRO, RFC, SERC, and SPP regional boundaries were altered as utilities changed reliability organizations. The historical data series for these regions have not been adjusted. Instead, the Balance of Eastern Region category was introduced to to provide a consistent trend of the Eastern interconnection.
A25: • ECAR, MAAC, and MAIN dissolved at the end-of-2005. Many of the former utility members joined RFC. ReliabilityFirst Corporation (RFC) came into existence on January 1, 2006. RFC submitted a consolidated filing covering the historical NERC regions of ECAR, MAAC, and MAIN.
A26: • MAPP was absorbed into MISO, SPP and WECC in 2015.
A27: • E - Estimate; NA - Not Available
A28: Source: U.S. Energy Information Administration, Form EIA-411, "Coordinated Bulk Power Supply and Demand Program Report."

Sheet Calculations
A1: Seasonal Peak Month
A2: Balancing Area | B2: Reliability Area | C2: Summer | D2: Winter
A3: CAISO | B3: WECC | C3: =INDEX(INDIRECT(B3&"!$C$8:$N$8"),1,MATCH(MAX(INDIRECT(B3&"!$C$31:$N$31")),INDIRECT(B3&"!$C$31:$N$31"),0)) -> July | D3: =INDEX(INDIRECT(B3&"!$C$8:$N$8"),1,MATCH(MAX(INDIRECT(B3&"!$M$31:$N$31"),INDIRECT(B3&"!$C$31")),INDIRECT(B3&"!$C$31:$N$31"),0)) -> December
A4: ERCOT | B4: TRE | C4: =INDEX(INDIRECT(B4&"!$C$8:$N$8"),1,MATCH(MAX(INDIRECT(B4&"!$C$31:$N$31")),INDIRECT(B4&"!$C$31:$N$31"),0)) -> August | D4: =INDEX(INDIRECT(B4&"!$C$8:$N$8"),1,MATCH(MAX(INDIRECT(B4&"!$M$31:$N$31"),INDIRECT(B4&"!$C$31")),INDIRECT(B4&"!$C$31:$N$31"),0)) -> January
A5: MISO | B5: MISO | C5: =INDEX(INDIRECT(B5&"!$C$8:$N$8"),1,MATCH(MAX(INDIRECT(B5&"!$C$31:$N$31")),INDIRECT(B5&"!$C$31:$N$31"),0)) -> August | D5: =INDEX(INDIRECT(B5&"!$C$8:$N$8"),1,MATCH(MAX(INDIRECT(B5&"!$M$31:$N$31"),INDIRECT(B5&"!$C$31")),INDIRECT(B5&"!$C$31:$N$31"),0)) -> January
A6: SPP | B6: SPP | C6: =INDEX(INDIRECT(B6&"!$C$8:$N$8"),1,MATCH(MAX(INDIRECT(B6&"!$C$31:$N$31")),INDIRECT(B6&"!$C$31:$N$31"),0)) -> July | D6: =INDEX(INDIRECT(B6&"!$C$8:$N$8"),1,MATCH(MAX(INDIRECT(B6&"!$M$31:$N$31"),INDIRECT(B6&"!$C$31")),INDIRECT(B6&"!$C$31:$N$31"),0)) -> January
A7: NYISO | B7: NPCC | C7: =INDEX(INDIRECT(B7&"!$C$8:$N$8"),1,MATCH(MAX(INDIRECT(B7&"!$C$31:$N$31")),INDIRECT(B7&"!$C$31:$N$31"),0)) -> July | D7: =INDEX(INDIRECT(B7&"!$C$8:$N$8"),1,MATCH(MAX(INDIRECT(B7&"!$M$31:$N$31"),INDIRECT(B7&"!$C$31")),INDIRECT(B7&"!$C$31:$N$31"),0)) -> January
A8: ISO-NE | B8: NPCC | C8: =INDEX(INDIRECT(B8&"!$C$8:$N$8"),1,MATCH(MAX(INDIRECT(B8&"!$C$31:$N$31")),INDIRECT(B8&"!$C$31:$N$31"),0)) -> July | D8: =INDEX(INDIRECT(B8&"!$C$8:$N$8"),1,MATCH(MAX(INDIRECT(B8&"!$M$31:$N$31"),INDIRECT(B8&"!$C$31")),INDIRECT(B8&"!$C$31:$N$31"),0)) -> January
A12: Peak Month Capacity Factors (most recent year)
A13: Balancing Area | B13: Electricity Source | C13: Summer | D13: Winter | E13: Annual Load
A14: CAISO | B14: solar pv | C14: ='CAISO - CF'!C16 -> 0.39 | D14: ='CAISO - CF'!C21 -> 0 | E14: =INDEX($B$56:$B$62,MATCH(A14,$A$56:$A$62,0),1) -> 214955
A15: ERCOT | B15: solar pv | C15: ='ERCOT - CF'!F36 -> 0.76320678 | D15: ='ERCOT - CF'!F23 -> 0.068617832 | E15: =INDEX($B$56:$B$62,MATCH(A15,$A$56:$A$62,0),1) -> 373761.96
A16: MISO | B16: solar pv | C16: 0.5 | E16: =INDEX($B$56:$B$62,MATCH(A16,$A$56:$A$62,0),1) -> 730209.6
A17: SPP | B17: solar pv | C17: 0.607 | E17: =INDEX($B$56:$B$62,MATCH(A17,$A$56:$A$62,0),1) -> 259340.6
A18: NYISO | B18: solar pv | E18: =INDEX($B$56:$B$62,MATCH(A18,$A$56:$A$62,0),1) -> 155848
A19: ISO-NE | B19: solar pv | E19: =INDEX($B$56:$B$62,MATCH(A19,$A$56:$A$62,0),1) -> 141514
A20: PJM | B20: solar pv | C20: 0.6 | E20: =INDEX($B$56:$B$62,MATCH(A20,$A$56:$A$62,0),1) -> 823890
A21: CAISO | B21: onshore wind | C21: ='CAISO - CF'!C32 -> 0.23 | D21: ='CAISO - CF'!C37 -> 0.13 | E21: =INDEX($B$56:$B$62,MATCH(A21,$A$56:$A$62,0),1) -> 214955
A22: ERCOT | B22: onshore wind | C22: =SUM(SUMPRODUCT('ERCOT - CF'!C48:C50,'ERCOT - CF'!D48:D50),SUMPRODUCT('ERCOT - CF'!E48:E50,'ERCOT - CF'!F48:F50),SUMPRODUCT('ERCOT - CF'!G48:G50,'ERCOT - CF'!H48:H50))/SUM('ERCOT - CF'!D48:D50,'ERCOT - CF'!F48:F50,'ERCOT - CF'!H48:H50) -> 0.26932471 | D22: =SUM(SUMPRODUCT('ERCOT - CF'!C7:C9,'ERCOT - CF'!D7:D9),SUMPRODUCT('ERCOT - CF'!E7:E9,'ERCOT - CF'!F7:F9),SUMPRODUCT('ERCOT - CF'!G7:G9,'ERCOT - CF'!H7:H9))/SUM('ERCOT - CF'!D7:D9,'ERCOT - CF'!F7:F9,'ERCOT - CF'!H7:H9) -> 0.270788 | E22: =INDEX($B$56:$B$62,MATCH(A22,$A$56:$A$62,0),1) -> 373761.96
A23: MISO | B23: onshore wind | C23: 0.166 | E23: =INDEX($B$56:$B$62,MATCH(A23,$A$56:$A$62,0),1) -> 730209.6
A24: SPP | B24: onshore wind | C24: 0.28 | E24: =INDEX($B$56:$B$62,MATCH(A24,$A$56:$A$62,0),1) -> 259340.6
A25: NYISO | B25: onshore wind | C25: 0.19 | D25: 0.37 | E25: =INDEX($B$56:$B$62,MATCH(A25,$A$56:$A$62,0),1) -> 155848
A26: ISO-NE | B26: onshore wind | C26: 0.15 | D26: 0.3 | E26: =INDEX($B$56:$B$62,MATCH(A26,$A$56:$A$62,0),1) -> 141514
A27: PJM | B27: onshore wind | C27: 0.176 | E27: =INDEX($B$56:$B$62,MATCH(A27,$A$56:$A$62,0),1) -> 823890
A28: CAISO | B28: solar thermal | C28: ='CAISO - CF'!C16 -> 0.39 | D28: ='CAISO - CF'!C21 -> 0 | E28: =INDEX($B$56:$B$62,MATCH(A28,$A$56:$A$62,0),1) -> 214955
A29: ERCOT | B29: solar thermal | E29: =INDEX($B$56:$B$62,MATCH(A29,$A$56:$A$62,0),1) -> 373761.96
A30: MISO | B30: solar thermal | E30: =INDEX($B$56:$B$62,MATCH(A30,$A$56:$A$62,0),1) -> 730209.6
A31: SPP | B31: solar thermal | E31: =INDEX($B$56:$B$62,MATCH(A31,$A$56:$A$62,0),1) -> 259340.6
A32: NYISO | B32: solar thermal | E32: =INDEX($B$56:$B$62,MATCH(A32,$A$56:$A$62,0),1) -> 155848
A33: ISO-NE | B33: solar thermal | E33: =INDEX($B$56:$B$62,MATCH(A33,$A$56:$A$62,0),1) -> 141514
A34: CAISO | B34: biomass | C34: ='CAISO - CF'!F55 -> 0.87 | D34: ='CAISO - CF'!F60 -> 0.86 | E34: =INDEX($B$56:$B$62,MATCH(A34,$A$56:$A$62,0),1) -> 214955
A35: ERCOT | B35: biomass | E35: =INDEX($B$56:$B$62,MATCH(A35,$A$56:$A$62,0),1) -> 373761.96
A36: MISO | B36: biomass | E36: =INDEX($B$56:$B$62,MATCH(A36,$A$56:$A$62,0),1) -> 730209.6
A37: SPP | B37: biomass | E37: =INDEX($B$56:$B$62,MATCH(A37,$A$56:$A$62,0),1) -> 259340.6
A38: NYISO | B38: biomass | E38: =INDEX($B$56:$B$62,MATCH(A38,$A$56:$A$62,0),1) -> 155848
A39: ISO-NE | B39: biomass | E39: =INDEX($B$56:$B$62,MATCH(A39,$A$56:$A$62,0),1) -> 141514
A40: CAISO | B40: geothermal | C40: ='CAISO - CF'!F85 -> 0.84 | D40: ='CAISO - CF'!F90 -> 0.95 | E40: =INDEX($B$56:$B$62,MATCH(A40,$A$56:$A$62,0),1) -> 214955
A41: ERCOT | B41: geothermal | E41: =INDEX($B$56:$B$62,MATCH(A41,$A$56:$A$62,0),1) -> 373761.96
A42: MISO | B42: geothermal | E42: =INDEX($B$56:$B$62,MATCH(A42,$A$56:$A$62,0),1) -> 730209.6
A43: SPP | B43: geothermal | E43: =INDEX($B$56:$B$62,MATCH(A43,$A$56:$A$62,0),1) -> 259340.6
...

Sheet PTCF
A1: Unit: dimensionless (peak time capacity factors) | B1: summer | C1: winter
A2: hard coal | B2: =IFERROR(SUMPRODUCT(IF(Calculations!$B$14:$B$53=PTCF!A2,Calculations!$C$14:$C$53),IF(Calculations!$B$14:$B$53=PTCF!A2,Calculations!$E$14:$E$53))/SUMIFS(Calculations!$E$14:$E$53,Calculations!$B$14:$B$53,PTCF!A2,Calculations!$C$14:$C$53,"<>"&""),0.9) -> 0.9 | C2: =IFERROR(SUMPRODUCT(IF(Calculations!$B$14:$B$53=PTCF!A2,Calculations!$D$14:$D$53),IF(Calculations!$B$14:$B$53=PTCF!A2,Calculations!$E$14:$E$53))/SUMIFS(Calculations!$E$14:$E$53,Calculations!$B$14:$B$53,PTCF!A2,Calculations!$D$14:$D$53,"<>"&""),0.9) -> 0.9
A3: natural gas steam turbine | B3: =IFERROR(SUMPRODUCT(IF(Calculations!$B$14:$B$53=PTCF!A3,Calculations!$C$14:$C$53),IF(Calculations!$B$14:$B$53=PTCF!A3,Calculations!$E$14:$E$53))/SUMIFS(Calculations!$E$14:$E$53,Calculations!$B$14:$B$53,PTCF!A3,Calculations!$C$14:$C$53,"<>"&""),0.9) -> 0.9 | C3: =IFERROR(SUMPRODUCT(IF(Calculations!$B$14:$B$53=PTCF!A3,Calculations!$D$14:$D$53),IF(Calculations!$B$14:$B$53=PTCF!A3,Calculations!$E$14:$E$53))/SUMIFS(Calculations!$E$14:$E$53,Calculations!$B$14:$B$53,PTCF!A3,Calculations!$D$14:$D$53,"<>"&""),0.9) -> 0.9
A4: natural gas combined cycle | B4: =IFERROR(SUMPRODUCT(IF(Calculations!$B$14:$B$53=PTCF!A4,Calculations!$C$14:$C$53),IF(Calculations!$B$14:$B$53=PTCF!A4,Calculations!$E$14:$E$53))/SUMIFS(Calculations!$E$14:$E$53,Calculations!$B$14:$B$53,PTCF!A4,Calculations!$C$14:$C$53,"<>"&""),0.9) -> 0.9 | C4: =IFERROR(SUMPRODUCT(IF(Calculations!$B$14:$B$53=PTCF!A4,Calculations!$D$14:$D$53),IF(Calculations!$B$14:$B$53=PTCF!A4,Calculations!$E$14:$E$53))/SUMIFS(Calculations!$E$14:$E$53,Calculations!$B$14:$B$53,PTCF!A4,Calculations!$D$14:$D$53,"<>"&""),0.9) -> 0.9
A5: nuclear | B5: =IFERROR(SUMPRODUCT(IF(Calculations!$B$14:$B$53=PTCF!A5,Calculations!$C$14:$C$53),IF(Calculations!$B$14:$B$53=PTCF!A5,Calculations!$E$14:$E$53))/SUMIFS(Calculations!$E$14:$E$53,Calculations!$B$14:$B$53,PTCF!A5,Calculations!$C$14:$C$53,"<>"&""),0.9) -> 0.9 | C5: =IFERROR(SUMPRODUCT(IF(Calculations!$B$14:$B$53=PTCF!A5,Calculations!$D$14:$D$53),IF(Calculations!$B$14:$B$53=PTCF!A5,Calculations!$E$14:$E$53))/SUMIFS(Calculations!$E$14:$E$53,Calculations!$B$14:$B$53,PTCF!A5,Calculations!$D$14:$D$53,"<>"&""),0.9) -> 0.9
A6: hydro | B6: {=IFERROR(SUMPRODUCT(IF(Calculations!$B$14:$B$53=PTCF!A6,Calculations!$C$14:$C$53),IF(Calculations!$B$14:$B$53=PTCF!A6,Calculations!$E$14:$E$53))/SUMIFS(Calculations!$E$14:$E$53,Calculations!$B$14:$B$53,PTCF!A6,Calculations!$C$14:$C$53,"<>"&""),1)} -> 0.73 | C6: {=IFERROR(SUMPRODUCT(IF(Calculations!$B$14:$B$53=PTCF!A6,Calculations!$D$14:$D$53),IF(Calculations!$B$14:$B$53=PTCF!A6,Calculations!$E$14:$E$53))/SUMIFS(Calculations!$E$14:$E$53,Calculations!$B$14:$B$53,PTCF!A6,Calculations!$D$14:$D$53,"<>"&""),1)} -> 0.64
A7: onshore wind | B7: {=IFERROR(SUMPRODUCT(IF(Calculations!$B$14:$B$53=PTCF!A7,Calculations!$C$14:$C$53),IF(Calculations!$B$14:$B$53=PTCF!A7,Calculations!$E$14:$E$53))/SUMIFS(Calculations!$E$14:$E$53,Calculations!$B$14:$B$53,PTCF!A7,Calculations!$C$14:$C$53,"<>"&""),1)} -> 0.19995265 | C7: {=IFERROR(SUMPRODUCT(IF(Calculations!$B$14:$B$53=PTCF!A7,Calculations!$D$14:$D$53),IF(Calculations!$B$14:$B$53=PTCF!A7,Calculations!$E$14:$E$53))/SUMIFS(Calculations!$E$14:$E$53,Calculations!$B$14:$B$53,PTCF!A7,Calculations!$D$14:$D$53,"<>"&""),1)} -> 0.25874936
A8: solar pv | B8: {=IFERROR(SUMPRODUCT(IF(Calculations!$B$14:$B$53=PTCF!A8,Calculations!$C$14:$C$53),IF(Calculations!$B$14:$B$53=PTCF!A8,Calculations!$E$14:$E$53))/SUMIFS(Calculations!$E$14:$E$53,Calculations!$B$14:$B$53,PTCF!A8,Calculations!$C$14:$C$53,"<>"&""),1)} -> 0.57696003 | C8: {=IFERROR(SUMPRODUCT(IF(Calculations!$B$14:$B$53=PTCF!A8,Calculations!$D$14:$D$53),IF(Calculations!$B$14:$B$53=PTCF!A8,Calculations!$E$14:$E$53))/SUMIFS(Calculations!$E$14:$E$53,Calculations!$B$14:$B$53,PTCF!A8,Calculations!$D$14:$D$53,"<>"&""),1)} -> 0.043563779
A9: solar thermal | B9: {=IFERROR(SUMPRODUCT(IF(Calculations!$B$14:$B$53=PTCF!A9,Calculations!$C$14:$C$53),IF(Calculations!$B$14:$B$53=PTCF!A9,Calculations!$E$14:$E$53))/SUMIFS(Calculations!$E$14:$E$53,Calculations!$B$14:$B$53,PTCF!A9,Calculations!$C$14:$C$53,"<>"&""),1)} -> 0.39 | C9: {=IFERROR(SUMPRODUCT(IF(Calculations!$B$14:$B$53=PTCF!A9,Calculations!$D$14:$D$53),IF(Calculations!$B$14:$B$53=PTCF!A9,Calculations!$E$14:$E$53))/SUMIFS(Calculations!$E$14:$E$53,Calculations!$B$14:$B$53,PTCF!A9,Calculations!$D$14:$D$53,"<>"&""),1)} -> 0
A10: biomass | B10: {=IFERROR(SUMPRODUCT(IF(Calculations!$B$14:$B$53=PTCF!A10,Calculations!$C$14:$C$53),IF(Calculations!$B$14:$B$53=PTCF!A10,Calculations!$E$14:$E$53))/SUMIFS(Calculations!$E$14:$E$53,Calculations!$B$14:$B$53,PTCF!A10,Calculations!$C$14:$C$53,"<>"&""),1)} -> 0.87 | C10: {=IFERROR(SUMPRODUCT(IF(Calculations!$B$14:$B$53=PTCF!A10,Calculations!$D$14:$D$53),IF(Calculations!$B$14:$B$53=PTCF!A10,Calculations!$E$14:$E$53))/SUMIFS(Calculations!$E$14:$E$53,Calculations!$B$14:$B$53,PTCF!A10,Calculations!$D$14:$D$53,"<>"&""),1)} -> 0.86
A11: geothermal | B11: =IFERROR(SUMPRODUCT(IF(Calculations!$B$14:$B$53=PTCF!A11,Calculations!$C$14:$C$53),IF(Calculations!$B$14:$B$53=PTCF!A11,Calculations!$E$14:$E$53))/SUMIFS(Calculations!$E$14:$E$53,Calculations!$B$14:$B$53,PTCF!A11,Calculations!$C$14:$C$53,"<>"&""),0.9) -> 0.9 | C11: =IFERROR(SUMPRODUCT(IF(Calculations!$B$14:$B$53=PTCF!A11,Calculations!$D$14:$D$53),IF(Calculations!$B$14:$B$53=PTCF!A11,Calculations!$E$14:$E$53))/SUMIFS(Calculations!$E$14:$E$53,Calculations!$B$14:$B$53,PTCF!A11,Calculations!$D$14:$D$53,"<>"&""),0.9) -> 0.9
A12: petroleum | B12: =IFERROR(SUMPRODUCT(IF(Calculations!$B$14:$B$53=PTCF!A12,Calculations!$C$14:$C$53),IF(Calculations!$B$14:$B$53=PTCF!A12,Calculations!$E$14:$E$53))/SUMIFS(Calculations!$E$14:$E$53,Calculations!$B$14:$B$53,PTCF!A12,Calculations!$C$14:$C$53,"<>"&""),0.9) -> 0.9 | C12: =IFERROR(SUMPRODUCT(IF(Calculations!$B$14:$B$53=PTCF!A12,Calculations!$D$14:$D$53),IF(Calculations!$B$14:$B$53=PTCF!A12,Calculations!$E$14:$E$53))/SUMIFS(Calculations!$E$14:$E$53,Calculations!$B$14:$B$53,PTCF!A12,Calculations!$D$14:$D$53,"<>"&""),0.9) -> 0.9
A13: natural gas nonpeaker | B13: =IFERROR(SUMPRODUCT(IF(Calculations!$B$14:$B$53=PTCF!A13,Calculations!$C$14:$C$53),IF(Calculations!$B$14:$B$53=PTCF!A13,Calculations!$E$14:$E$53))/SUMIFS(Calculations!$E$14:$E$53,Calculations!$B$14:$B$53,PTCF!A13,Calculations!$C$14:$C$53,"<>"&""),0.9) -> 0.9 | C13: =IFERROR(SUMPRODUCT(IF(Calculations!$B$14:$B$53=PTCF!A13,Calculations!$D$14:$D$53),IF(Calculations!$B$14:$B$53=PTCF!A13,Calculations!$E$14:$E$53))/SUMIFS(Calculations!$E$14:$E$53,Calculations!$B$14:$B$53,PTCF!A13,Calculations!$D$14:$D$53,"<>"&""),0.9) -> 0.9
A14: lignite | B14: =IFERROR(SUMPRODUCT(IF(Calculations!$B$14:$B$53=PTCF!A14,Calculations!$C$14:$C$53),IF(Calculations!$B$14:$B$53=PTCF!A14,Calculations!$E$14:$E$53))/SUMIFS(Calculations!$E$14:$E$53,Calculations!$B$14:$B$53,PTCF!A14,Calculations!$C$14:$C$53,"<>"&""),0.9) -> 0.9 | C14: =IFERROR(SUMPRODUCT(IF(Calculations!$B$14:$B$53=PTCF!A14,Calculations!$D$14:$D$53),IF(Calculations!$B$14:$B$53=PTCF!A14,Calculations!$E$14:$E$53))/SUMIFS(Calculations!$E$14:$E$53,Calculations!$B$14:$B$53,PTCF!A14,Calculations!$D$14:$D$53,"<>"&""),0.9) -> 0.9
A15: offshore wind | B15: {=IFERROR(SUMPRODUCT(IF(Calculations!$B$14:$B$53=PTCF!A15,Calculations!$C$14:$C$53),IF(Calculations!$B$14:$B$53=PTCF!A15,Calculations!$E$14:$E$53))/SUMIFS(Calculations!$E$14:$E$53,Calculations!$B$14:$B$53,PTCF!A15,Calculations!$C$14:$C$53,"<>"&""),1)} -> 0.31861529 | C15: {=IFERROR(SUMPRODUCT(IF(Calculations!$B$14:$B$53=PTCF!A15,Calculations!$D$14:$D$53),IF(Calculations!$B$14:$B$53=PTCF!A15,Calculations!$E$14:$E$53))/SUMIFS(Calculations!$E$14:$E$53,Calculations!$B$14:$B$53,PTCF!A15,Calculations!$D$14:$D$53,"<>"&""),1)} -> 0.61951796
A16: crude oil | B16: =IFERROR(SUMPRODUCT(IF(Calculations!$B$14:$B$53=PTCF!A16,Calculations!$C$14:$C$53),IF(Calculations!$B$14:$B$53=PTCF!A16,Calculations!$E$14:$E$53))/SUMIFS(Calculations!$E$14:$E$53,Calculations!$B$14:$B$53,PTCF!A16,Calculations!$C$14:$C$53,"<>"&""),0.9) -> 0.9 | C16: =IFERROR(SUMPRODUCT(IF(Calculations!$B$14:$B$53=PTCF!A16,Calculations!$D$14:$D$53),IF(Calculations!$B$14:$B$53=PTCF!A16,Calculations!$E$14:$E$53))/SUMIFS(Calculations!$E$14:$E$53,Calculations!$B$14:$B$53,PTCF!A16,Calculations!$D$14:$D$53,"<>"&""),0.9) -> 0.9
A17: heavy or residual fuel oil | B17: =IFERROR(SUMPRODUCT(IF(Calculations!$B$14:$B$53=PTCF!A17,Calculations!$C$14:$C$53),IF(Calculations!$B$14:$B$53=PTCF!A17,Calculations!$E$14:$E$53))/SUMIFS(Calculations!$E$14:$E$53,Calculations!$B$14:$B$53,PTCF!A17,Calculations!$C$14:$C$53,"<>"&""),0.9) -> 0.9 | C17: =IFERROR(SUMPRODUCT(IF(Calculations!$B$14:$B$53=PTCF!A17,Calculations!$D$14:$D$53),IF(Calculations!$B$14:$B$53=PTCF!A17,Calculations!$E$14:$E$53))/SUMIFS(Calculations!$E$14:$E$53,Calculations!$B$14:$B$53,PTCF!A17,Calculations!$D$14:$D$53,"<>"&""),0.9) -> 0.9
A18: municipal solid waste | B18: =IFERROR(SUMPRODUCT(IF(Calculations!$B$14:$B$53=PTCF!A18,Calculations!$C$14:$C$53),IF(Calculations!$B$14:$B$53=PTCF!A18,Calculations!$E$14:$E$53))/SUMIFS(Calculations!$E$14:$E$53,Calculations!$B$14:$B$53,PTCF!A18,Calculations!$C$14:$C$53,"<>"&""),0.9) -> 0.9 | C18: =IFERROR(SUMPRODUCT(IF(Calculations!$B$14:$B$53=PTCF!A18,Calculations!$D$14:$D$53),IF(Calculations!$B$14:$B$53=PTCF!A18,Calculations!$E$14:$E$53))/SUMIFS(Calculations!$E$14:$E$53,Calculations!$B$14:$B$53,PTCF!A18,Calculations!$D$14:$D$53,"<>"&""),0.9) -> 0.9
A19: hard coal w CCS | B19: =$B$18 -> 0.9 | C19: =$B$18 -> 0.9
A20: natural gas combined cycle w CCS | B20: =$B$18 -> 0.9 | C20: =$B$18 -> 0.9
A21: biomass w CCS | B21: =$B$18 -> 0.9 | C21: =$B$18 -> 0.9
A22: lignite w CCS | B22: =$B$18 -> 0.9 | C22: =$B$18 -> 0.9
A23: small modular reactor | B23: =$B$18 -> 0.9 | C23: =$B$18 -> 0.9
A24: hydrogen combustion turbine | B24: =$B$18 -> 0.9 | C24: =$B$18 -> 0.9
A25: hydrogen combined cycle | B25: 0.9 | C25: 0.9
