Workbook
Name Eno_TM: #REF!
Name Eno_TM: #REF!
Name Eno_TM: #REF!
Name Eno_Tons: #REF!
Name Eno_Tons: #REF!
Name Eno_Tons: #REF!
Name NTS_YR: #REF!
Name Sum_T2: #REF!
Name Sum_T2: #REF!
Name Sum_T2: #REF!
Name Sum_TTM: #REF!
Name Sum_TTM: #REF!
Name Sum_TTM: #REF!
Name ti_tbl_50: #REF!
Name ti_tbl_50: #REF!
Name ti_tbl_50: #REF!
Name ti_tbl_69: #REF!
Name ti_tbl_69: #REF!
Name ti_tbl_69: #REF!

Sheet About
A1: BCDTRtSY BAU Cargo Dist Transported Relative to Start Year | B1: Louisiana | C1: 45660 | E1: State | F1: State
B2: =LOOKUP(B1,E2:F51,F2:F51) -> LA | E2: Alabama | F2: AL
A3: Sources: | B3: See Notes section for which vehicle types use which sources | E3: Alaska | F3: AK
B4: EIA | E4: Arizona | F4: AZ
B5: 2020, 2021, 2022 | E5: Arkansas | F5: AR
B6: Annual Energy Outlook 2020, 2021, and 2022 | E6: California | F6: CA
B7: https://www.eia.gov/outlooks/aeo/tables_side.php | E7: Colorado | F7: CO
B8: Tables 7, 36, 46, 47, 49 | E8: Connecticut | F8: CT
E9: Delaware | F9: DE
B10: Bus adjustment factor, 2020-2025 | E10: Florida | F10: FL
B11: EPA | E11: Georgia | F11: GA
B12: 2022 | E12: Hawaii | F12: HI
B13: Inventory of U.S. Greenhouse Gas Emissions and Sinks: 1990-2020 | E13: Idaho | F13: ID
B14: https://www.epa.gov/ghgemissions/inventory-us-greenhouse-gas-emissions-and-sinks-1990-2020 | E14: Illinois | F14: IL
B15: Table 3-13 | E15: Indiana | F15: IN
E16: Iowa | F16: IA
B17: SEDS state data | E17: Kansas | F17: KS
B18: EIA | E18: Kentucky | F18: KY
B19: 2024 | E19: Louisiana | F19: LA
B20: SEDS | E20: Maine | F20: ME
B21: https://www.eia.gov/state/seds/ | E21: Maryland | F21: MD
E22: Massachusetts | F22: MA
E23: Michigan | F23: MI
A24: Notes | E24: Minnesota | F24: MN
A25: This variable contains ratios of cargo distance transported in each year of the | E25: Mississippi | F25: MS
A26: model run relative to the start year. The start year is the year before the | E26: Missouri | F26: MO
A27: first simulated year. So if the first year for which the model outputs data | E27: Montana | F27: MT
A28: is 2020, the start year is 2019. The start year column does not have to be | E28: Nebraska | F28: NE
A29: included in the outputs but is retained here for visual clarity. | E29: Nevada | F29: NV
A30: We use AEO 2021 to calculate start year vehicles, as AEO 2021 does not include 2019 data. | E30: New Hampshire | F30: NH
E31: New Jersey | F31: NJ
A32: We scale by passenger-miles, freight ton-miles, or vehicle-miles where available. | E32: New Mexico | F32: NM
A33: (We assume vehicle loading remains constant, so scaling by vehicle-miles is | E33: New York | F33: NY
A34: identical to scaling by passenger-miles or freight ton-miles.) | E34: North Carolina | F34: NC
E35: North Dakota | F35: ND
A36: We classify AEO's light commercial trucks category as well as light-medium and medium duty vehicles | E36: Ohio | F36: OH
A37: in "freight LDVs" and heavy duty vehicles in "freight HDVs." | E37: Oklahoma | F37: OK
E38: Oregon | F38: OR
A39: Without any calibration adjustment, the very large dip in passenger air travel in 2020 leads to discrepancies | E39: Pennsylvania | F39: PA
A40: in energy use between AEO and the EPS outputs given our current methodology. Therefore, we add a calibration | E40: Rhode Island | F40: RI
...

Sheet SEDS 2022
A1: Data_Status | B1: State | C1: MSN | D1: 2019 | E1: 2020 | F1: 2021 | G1: 2022
A2: 2022F | B2: AK | C2: ABICB | D2: -10 | E2: -7 | F2: -8 | G2: -6
A3: 2022F | B3: AK | C3: ARICB | D3: 11973 | E3: 12391 | F3: 13425 | G3: 12981
A4: 2022F | B4: AK | C4: ARTCB | D4: 11973 | E4: 12391 | F4: 13425 | G4: 12981
A5: 2022F | B5: AK | C5: ARTXB | D5: 11973 | E5: 12391 | F5: 13425 | G5: 12981
A6: 2022F | B6: AK | C6: AVACB | D6: 1245 | E6: 915 | F6: 1037 | G6: 1073
A7: 2022F | B7: AK | C7: AVTCB | D7: 1245 | E7: 915 | F7: 1037 | G7: 1073
A8: 2022F | B8: AK | C8: AVTXB | D8: 1245 | E8: 915 | F8: 1037 | G8: 1073
A9: 2022F | B9: AK | C9: B1ACB | D9: 0 | E9: 0 | F9: 0 | G9: 0
A10: 2022F | B10: AK | C10: B1TCB | D10: 0 | E10: 0 | F10: 0 | G10: 0
A11: 2022F | B11: AK | C11: BDACB | D11: 865 | E11: 865 | F11: 865 | G11: 865
A12: 2022F | B12: AK | C12: BDLCB | D12: 0 | E12: 0 | F12: 0 | G12: 0
... A14774: 2022F | B14774: WY | C14774: ZWHDP | D14774: 8906 | E14774: 8069 | F14774: 7865 | G14774: 8441

Sheet seds growth
A1: =About!B2 -> LA
E2: 2021 | F2: 2022 | G2: growth rate | H2: assigned veh type
A3: TNACB | C3: Transportation | D3: total | E3: =SUMIFS('SEDS 2022'!F:F,'SEDS 2022'!$C:$C,$A3,'SEDS 2022'!$B:$B,$A$1) -> 697925 | F3: =SUMIFS('SEDS 2022'!G:G,'SEDS 2022'!$C:$C,$A3,'SEDS 2022'!$B:$B,$A$1) -> 755840 | G3: =F3/E3 -> 1.0829817
A4: BDACB | C4: biofuel diesel | D4: biofuel diesel tf | E4: =SUMIFS('SEDS 2022'!F:F,'SEDS 2022'!$C:$C,$A4,'SEDS 2022'!$B:$B,$A$1) -> 4496 | F4: =SUMIFS('SEDS 2022'!G:G,'SEDS 2022'!$C:$C,$A4,'SEDS 2022'!$B:$B,$A$1) -> 4048 | G4: =F4/E4 -> 0.90035587
A5: EMACB | C5: biofuel gasoline | D5: biofuel gasoline tf | E5: =SUMIFS('SEDS 2022'!F:F,'SEDS 2022'!$C:$C,$A5,'SEDS 2022'!$B:$B,$A$1) -> 16805 | F5: =SUMIFS('SEDS 2022'!G:G,'SEDS 2022'!$C:$C,$A5,'SEDS 2022'!$B:$B,$A$1) -> 17757 | G5: =F5/E5 -> 1.0566498
A6: ESACB | C6: electricity | D6: electricity tf | E6: =SUMIFS('SEDS 2022'!F:F,'SEDS 2022'!$C:$C,$A6,'SEDS 2022'!$B:$B,$A$1) -> 32 | F6: =SUMIFS('SEDS 2022'!G:G,'SEDS 2022'!$C:$C,$A6,'SEDS 2022'!$B:$B,$A$1) -> 35 | G6: =F6/E6 -> 1.09375
A7: RFACB | C7: heavy or residual fuel oil | D7: heavy or residual fuel oil tf | E7: =SUMIFS('SEDS 2022'!F:F,'SEDS 2022'!$C:$C,$A7,'SEDS 2022'!$B:$B,$A$1) -> 38404 | F7: =SUMIFS('SEDS 2022'!G:G,'SEDS 2022'!$C:$C,$A7,'SEDS 2022'!$B:$B,$A$1) -> 39353 | G7: =F7/E7 -> 1.024711
A8: JFACB | B8: AVACB | C8: jet fuel | D8: jet fuel tf | E8: =SUMIFS('SEDS 2022'!F:F,'SEDS 2022'!$C:$C,$A8,'SEDS 2022'!$B:$B,$A$1) -> 16023 | F8: =SUMIFS('SEDS 2022'!G:G,'SEDS 2022'!$C:$C,$A8,'SEDS 2022'!$B:$B,$A$1) -> 20489 | G8: =F8/E8 -> 1.2787243 | H8: aircraft
A9: PQACB | C9: LPG propane or butane | D9: LPG propane or butane tf | E9: =SUMIFS('SEDS 2022'!F:F,'SEDS 2022'!$C:$C,$A9,'SEDS 2022'!$B:$B,$A$1) -> 188 | F9: =SUMIFS('SEDS 2022'!G:G,'SEDS 2022'!$C:$C,$A9,'SEDS 2022'!$B:$B,$A$1) -> 267 | G9: =F9/E9 -> 1.4202128
A10: NGACB | C10: natural gas | D10: natural gas tf | E10: =SUMIFS('SEDS 2022'!F:F,'SEDS 2022'!$C:$C,$A10,'SEDS 2022'!$B:$B,$A$1) -> 228773 | F10: =SUMIFS('SEDS 2022'!G:G,'SEDS 2022'!$C:$C,$A10,'SEDS 2022'!$B:$B,$A$1) -> 286412 | G10: =F10/E10 -> 1.2519484
A11: DFACB | C11: petroleum diesel | D11: petroleum diesel tf | E11: =SUMIFS('SEDS 2022'!F:F,'SEDS 2022'!$C:$C,$A11,'SEDS 2022'!$B:$B,$A$1) -> 154528 | F11: =SUMIFS('SEDS 2022'!G:G,'SEDS 2022'!$C:$C,$A11,'SEDS 2022'!$B:$B,$A$1) -> 156667 | G11: =F11/E11 -> 1.0138422 | H11: HDVs
A12: MGACB | C12: petroleum gasoline | D12: petroleum gasoline tf | E12: =SUMIFS('SEDS 2022'!F:F,'SEDS 2022'!$C:$C,$A12,'SEDS 2022'!$B:$B,$A$1) -> 254356 | F12: =SUMIFS('SEDS 2022'!G:G,'SEDS 2022'!$C:$C,$A12,'SEDS 2022'!$B:$B,$A$1) -> 247173 | G12: =F12/E12 -> 0.97176005 | H12: LDVs

Sheet EPA_Table 3-13
A1: Table 3-13: CO2 Emissions from Fossil Fuel Combustion in Transportation End-Use Sector (MMT CO2 Eq.)
A3: Fuel/Vehicle Type | B3: 2020 | C3: 2021 | G3: 2021 to 2020 growth rate
A4: Gasolinea | B4: 937 | C4: 1029 | F4: Buses | G4: =SUM(C8,C15,C35,C41,C45)/SUM(B45,B41,B35,B15,B8) -> 1.0416667
A5: Passenger Cars | B5: 328 | C5: 361
A6: Light-Duty Trucks | B6: 566 | C6: 620
A7: Medium- and Heavy-Duty Trucksb | B7: 24 | C7: 27
A8: Buses | B8: 3 | C8: 3
A9: Motorcycles | B9: 7 | C9: 7
A10: Recreational Boatsc | B10: 10 | C10: 11
A11: Distillate Fuel Oil (Diesel)a | B11: 455 | C11: 488
A12: Passenger Cars | B12: 3 | C12: 3
A13: Light-Duty Trucks | B13: 30 | C13: 33
A14: Medium- and Heavy-Duty Trucksb | B14: 353 | C14: 380
A15: Buses | B15: 20 | C15: 21
A16: Rail | B16: 31 | C16: 32
... A50: Biofuels-Biodieselh | B50: 17.7 | C50: 16.1
A51: + Does not exceed 0.05 MMT CO2 Eq.
A52: a On-road fuel consumption data from FHWA Table MF-21 and MF-27 were used to determine total on-road use of motor gasoline and diesel fuel (FHWA 1996 through 2023). Ratios developed from MOVES3 output are used to apportion FHWA fuel consumption data to vehicle type and fuel type (see Annex 3.2 for information about the MOVES model).
A53: b Includes medium- and heavy-duty trucks over 8,500 lbs.
A54: c In 2014, EPA incorporated the NONROAD2008 model into the MOVES model framework. The current Inventory uses the Nonroad component of MOVES3 for years 1999 through 2021. See Annex 3.2 for information about the MOVES model.
A55: d Note that large year over year fluctuations in emission estimates partially reflect nature of data collection for these sources.
A56: e Official estimates exclude emissions from the combustion of both aviation and marine international bunker fuels; however, estimates of international bunker fuel-related emissions are presented for informational purposes.
A57: f Commercial aircraft, as modeled in FAA’s Aviation Environmental Design Tool (AEDT), consists of passenger aircraft, cargo, and other chartered flights.
A58: g Pipelines reflect CO2 emissions from natural gas-powered pipelines transporting natural gas.
A59: h Ethanol and biodiesel estimates are presented for informational purposes only. See Section 3.10 of this chapter and the estimates in Land Use, Land-Use Change, and Forestry (see Chapter 6), in line with IPCC methodological guidance and UNFCCC reporting obligations, for more information on ethanol and biodiesel.
A60: i Transportation sector natural gas and LPG consumption are based on data from EIA (2021b). Prior to the 1990 to 2015 Inventory, data from DOE TEDB were used to estimate each vehicle class’s share of the total natural gas and LPG consumption. Since TEDB does not include estimates for natural gas use by medium and heavy-duty trucks or LPG use by passenger cars, EIA Alternative Fuel Vehicle Data (Browning 2017) is now used to determine each vehicle class’s share of the total natural gas and LPG consumption. These changes were first incorporated in the 1990 to 2016 Inventory and apply to the 1990 to 2021 time period.
A61: j Includes emissions from rail electricity.
A62: k Electricity consumption by passenger cars, light-duty trucks (SUVs), and buses is based on plug-in electric vehicle sales and engine efficiency data, as outlined in Browning (2018a). In prior Inventory years, CO2 emissions from electric vehicle charging were allocated to the residential and commercial sectors. They are now allocated to the transportation sector. These changes apply to the 2010 through 2021 time period.
A63: Notes: This table does not include emissions from non-transportation mobile sources, such as agricultural equipment and construction/mining equipment; it also does not include emissions associated with electricity consumption by pipelines or lubricants used in transportation. In addition, this table does not include CO2 emissions from U.S. Territories, since these are covered in a separate chapter of the Inventory. Totals may not sum due to independent rounding.

Sheet AEO 2021 Table 7
B1: highogs.d120120a | C1: 2020 | D1: 2021 | E1: 2022 | F1: 2023 | G1: 2024 | H1: 2025 | I1: 2026 | J1: 2027 | K1: 2028 | L1: 2029 | M1: 2030 | N1: 2031 | O1: 2032 | P1: 2033 | Q1: 2034 | R1: 2035 | S1: 2036 | T1: 2037 | U1: 2038 | V1: 2039 | W1: 2040 | X1: 2041 | Y1: 2042 | Z1: 2043 | AA1: 2044 | AB1: 2045 | AC1: 2046 | AD1: 2047 | AE1: 2048 | AF1: 2049 | AG1: 2050
C3: Report | D3: Annual Energy Outlook 2021
C4: Scenario | D4: ref2021 | G4: Reference case
C5: Datekey | D5: d113020a
C6: Release Date | E6: January 2021
A10: TKI000 | B10: 7. Transportation Sector Key Indicators and Delivered Energy Consumption | AH10: Compound
AH11: Growth
AH12: 2020-2050
B13: Key Indicators and Consumption | C13: 2020 | D13: 2021 | E13: 2022 | F13: 2023 | G13: 2024 | H13: 2025 | I13: 2026 | J13: 2027 | K13: 2028 | L13: 2029 | M13: 2030 | N13: 2031 | O13: 2032 | P13: 2033 | Q13: 2034 | R13: 2035 | S13: 2036 | T13: 2037 | U13: 2038 | V13: 2039 | W13: 2040 | X13: 2041 | Y13: 2042 | Z13: 2043 | AA13: 2044 | AB13: 2045 | AC13: 2046 | AD13: 2047 | AE13: 2048 | AF13: 2049 | AG13: 2050 | AH13: (percent)
B15: Key Indicators
B16: Travel Indicators
B17: (billion vehicle miles traveled)
A18: TKI000:ba_Light-DutyVeh | B18: Light-Duty Vehicles less than 8,501 pounds | C18: 2628.8213 | D18: 2807.2766 | E18: 2862.5334 | F18: 2927.623 | G18: 2985.1787 | H18: 3035.5583 | I18: 3076.646 | J18: 3107.3425 | K18: 3133.9348 | L18: 3153.6963 | M18: 3170.1406 | N18: 3182.3604 | O18: 3194.3308 | P18: 3208.3691 | Q18: 3223.0125 | R18: 3240.585 | S18: 3258.4961 | T18: 3274.8767 | U18: 3290.0166 | V18: 3306.9768 | W18: 3326.3066 | X18: 3344.3862 | Y18: 3362.8257 | Z18: 3380.6958 | AA18: 3396.752 | AB18: 3412.0305 | AC18: 3428.1084 | AD18: 3442.5149 | AE18: 3458.3401 | AF18: 3474.7087 | AG18: 3490.9399 | AH18: 0.009499
A19: TKI000:ba_CommercialLig | B19: Commercial Light Trucks 1/ | C19: 89.884674 | D19: 93.705605 | E19: 96.386086 | F19: 98.338295 | G19: 100.59341 | H19: 102.85941 | I19: 104.50481 | J19: 105.69051 | K19: 106.73648 | L19: 107.65262 | M19: 108.58299 | N19: 109.54169 | O19: 110.61884 | P19: 111.70705 | Q19: 112.95861 | R19: 114.4644 | S19: 115.90713 | T19: 117.2149 | U19: 118.58162 | V19: 120.04366 | W19: 121.52813 | X19: 123.15266 | Y19: 124.79562 | Z19: 126.54729 | AA19: 128.13809 | AB19: 129.78653 | AC19: 131.39938 | AD19: 132.81888 | AE19: 134.41592 | AF19: 136.18376 | AG19: 138.01 | AH19: 0.014396
A20: TKI000:ba_FreightTrucks | B20: Freight Trucks greater than 10,000 pounds | C20: 274.54938 | D20: 282.81525 | E20: 293.31253 | F20: 299.26825 | G20: 306.24057 | H20: 313.39252 | I20: 318.20425 | J20: 321.86676 | K20: 325.49912 | L20: 328.91818 | M20: 332.87759 | N20: 337.04804 | O20: 341.41943 | P20: 345.24298 | Q20: 349.75104 | R20: 355.3486 | S20: 360.47449 | T20: 365.30786 | U20: 370.46982 | V20: 375.98251 | W20: 381.01727 | X20: 386.70856 | Y20: 392.7948 | Z20: 399.70087 | AA20: 405.64847 | AB20: 411.79804 | AC20: 417.07053 | AD20: 422.22894 | AE20: 428.00507 | AF20: 434.11798 | AG20: 440.79153 | AH20: 0.015907
B21: (billion passenger miles traveled)
A22: TKI000:buspassmiles | B22: Bus Transportation | C22: 108.32251 | D22: 134.82925 | E22: 154.71742 | F22: 169.65283 | G22: 180.92081 | H22: 189.4493 | I22: 195.91775 | J22: 200.87158 | K22: 204.4294 | L22: 207.17819 | M22: 209.42627 | N22: 211.01544 | O22: 212.35484 | P22: 213.3685 | Q22: 214.16457 | R22: 214.70816 | S22: 215.16942 | T22: 215.53513 | U22: 215.80548 | V22: 215.98587 | W22: 216.16197 | X22: 216.26544 | Y22: 216.33122 | Z22: 216.37845 | AA22: 216.40999 | AB22: 216.44157 | AC22: 216.45151 | AD22: 216.46837 | AE22: 216.483 | AF22: 216.55254 | AG22: 216.64348 | AH22: 0.023374
A23: TKI000:railpassmiles | B23: Passenger Rail | C23: 24.970692 | D23: 29.653244 | E23: 33.486446 | F23: 36.386101 | G23: 38.577961 | H23: 40.222988 | I23: 41.396164 | J23: 42.264778 | K23: 42.515728 | L23: 42.713291 | M23: 43.137005 | N23: 43.343742 | O23: 43.818241 | P23: 44.274139 | Q23: 44.835865 | R23: 45.310886 | S23: 45.831734 | T23: 46.32793 | U23: 46.816154 | V23: 47.317448 | W23: 47.980492 | X23: 48.58215 | Y23: 49.164021 | Z23: 49.763081 | AA23: 50.334721 | AB23: 50.97802 | AC23: 51.558666 | AD23: 52.079247 | AE23: 52.647175 | AF23: 53.282265 | AG23: 53.912506 | AH23: 0.025987
B24: (billion seat miles available)
A25: TKI000:ba_Air | B25: Air | C25: 738.85895 | D25: 1081.6603 | E25: 1215.7373 | F25: 1284.3009 | G25: 1340.2419 | H25: 1397.254 | I25: 1430.9814 | J25: 1455.4497 | K25: 1476.5328 | L25: 1495.9988 | M25: 1516.3666 | N25: 1539.9563 | O25: 1569.8956 | P25: 1600.4498 | Q25: 1634.8596 | R25: 1672.6685 | S25: 1707.1351 | T25: 1738.4458 | U25: 1770.8867 | V25: 1807.5973 | W25: 1848.892 | X25: 1889.7706 | Y25: 1930.5969 | Z25: 1971.072 | AA25: 2010.4889 | AB25: 2052.9485 | AC25: 2092.6599 | AD25: 2129.1379 | AE25: 2171.0725 | AF25: 2213.2192 | AG25: 2256.3169 | AH25: 0.037914
B26: (billion ton miles traveled)
A27: TKI000:ba_Rail | B27: Rail | C27: 1508.557 | D27: 1600.7733 | E27: 1616.5277 | F27: 1618.1086 | G27: 1617.9658 | H27: 1567.8839 | I27: 1587.1537 | J27: 1586.3214 | K27: 1606.0509 | L27: 1623.5897 | M27: 1641.5112 | N27: 1654.2195 | O27: 1664.4609 | P27: 1678.1671 | Q27: 1686.5093 | R27: 1700.8228 | S27: 1714.3484 | T27: 1725.9465 | U27: 1730.047 | V27: 1747.595 | W27: 1753.4669 | X27: 1765.8125 | Y27: 1783.1677 | Z27: 1804.6465 | AA27: 1808.4172 | AB27: 1822.5868 | AC27: 1832.4125 | AD27: 1846.7275 | AE27: 1860.8992 | AF27: 1876.0131 | AG27: 1898.7479 | AH27: 0.007697
A28: TKI000:ba_DomesticShipp | B28: Domestic Shipping | C28: 347.68133 | D28: 359.32346 | E28: 357.10059 | F28: 354.90668 | G28: 352.6954 | H28: 348.07819 | I28: 341.28058 | J28: 333.10046 | K28: 325.25259 | L28: 316.86505 | M28: 308.73145 | N28: 305.11627 | O28: 301.85187 | P28: 298.30835 | Q28: 295.38019 | R28: 292.62634 | S28: 289.63 | T28: 286.27258 | U28: 282.6651 | V28: 279.71716 | W28: 276.01688 | X28: 275.42545 | Y28: 275.00784 | Z28: 275.36859 | AA28: 274.91849 | AB28: 274.56326 | AC28: 273.54471 | AD28: 272.61859 | AE28: 271.43494 | AF28: 270.55728 | AG28: 270.13117 | AH28: -0.008377
B30: Energy Efficiency Indicators
B31: (miles per gallon)
A32: TKI000:ca_AvgCAFEStand | B32: New Light-Duty Vehicle CAFE Standard 2/ | C32: 34.471165 | D32: 35.386478 | E32: 36.015511 | F32: 36.532135 | G32: 36.999756 | H32: 37.485561 | I32: 38.067947 | J32: 38.072563 | K32: 38.080814 | L32: 38.095245 | M32: 38.18074 | N32: 38.191765 | O32: 38.206318 | P32: 38.220623 | Q32: 38.249493 | R32: 38.23008 | S32: 38.209507 | T32: 38.204479 | U32: 38.204224 | V32: 38.187893 | W32: 38.180141 | X32: 38.173969 | Y32: 38.160957 | Z32: 38.151768 | AA32: 38.148342 | AB32: 38.153297 | AC32: 38.143864 | AD32: 38.134365 | AE32: 38.120548 | AF32: 38.116928 | AG32: 38.114223 | AH32: 0.003354
A33: TKI000:ca_CarCAFEStand | B33: New Car 2/ | C33: 42.096588 | D33: 44.275085 | E33: 44.804096 | F33: 45.431927 | G33: 46.163593 | H33: 46.83271 | I33: 47.617275 | J33: 47.640335 | K33: 47.640335 | L33: 47.644814 | M33: 47.681995 | N33: 47.681995 | O33: 47.681995 | P33: 47.681995 | Q33: 47.681995 | R33: 47.681995 | S33: 47.681995 | T33: 47.681995 | U33: 47.681995 | V33: 47.681995 | W33: 47.681995 | X33: 47.681995 | Y33: 47.681995 | Z33: 47.683205 | AA33: 47.684814 | AB33: 47.687138 | AC33: 47.687138 | AD33: 47.687138 | AE33: 47.687138 | AF33: 47.689449 | AG33: 47.689449 | AH33: 0.004167
A34: TKI000:ca_TwukCAFEStand | B34: New Light Truck 2/ | C34: 30.906752 | D34: 31.515783 | E34: 31.942911 | F34: 32.461285 | G34: 32.91795 | H34: 33.400791 | I34: 33.955074 | J34: 33.955074 | K34: 33.955074 | L34: 33.955074 | M34: 33.955074 | N34: 33.955093 | O34: 33.955093 | P34: 33.955093 | Q34: 33.955093 | R34: 33.955128 | S34: 33.955128 | T34: 33.955128 | U34: 33.955128 | V34: 33.955128 | W34: 33.955128 | X34: 33.955128 | Y34: 33.955128 | Z34: 33.955128 | AA34: 33.955128 | AB34: 33.955128 | AC34: 33.955128 | AD34: 33.955128 | AE34: 33.955128 | AF34: 33.955128 | AG34: 33.955128 | AH34: 0.00314
A35: TKI000:ca_NewVehCred | B35: Compliance New Light-Duty Vehicle 3/ | C35: 35.428043 | D35: 36.588161 | E35: 37.27243 | F35: 37.693687 | G35: 38.000156 | H35: 38.414772 | I35: 38.930225 | J35: 39.067493 | K35: 39.131561 | L35: 39.187084 | M35: 39.367001 | N35: 39.458767 | O35: 39.570412 | P35: 39.688381 | Q35: 39.842903 | R35: 39.925739 | S35: 40.007633 | T35: 40.122059 | U35: 40.263226 | V35: 40.363659 | W35: 40.483315 | X35: 40.567554 | Y35: 40.636898 | Z35: 40.715225 | AA35: 40.813824 | AB35: 40.933929 | AC35: 41.032745 | AD35: 41.136253 | AE35: 41.233734 | AF35: 41.366283 | AG35: 41.510693 | AH35: 0.005296
A36: TKI000:ca_NewCarCred | B36: New Car 3/ | C36: 43.264011 | D36: 45.133469 | E36: 45.638382 | F36: 46.329559 | G36: 46.974045 | H36: 47.544498 | I36: 48.288284 | J36: 48.41925 | K36: 48.519196 | L36: 48.602192 | M36: 48.75803 | N36: 48.944359 | O36: 49.116051 | P36: 49.343533 | Q36: 49.588879 | R36: 49.838387 | S36: 50.062164 | T36: 50.324268 | U36: 50.609341 | V36: 50.887779 | W36: 51.161552 | X36: 51.375084 | Y36: 51.577618 | Z36: 51.784939 | AA36: 52.021469 | AB36: 52.278286 | AC36: 52.554256 | AD36: 52.823685 | AE36: 53.105881 | AF36: 53.415283 | AG36: 53.766708 | AH36: 0.007271
A37: TKI000:ca_NewTwukCred | B37: New Light Truck 3/ | C37: 31.76507 | D37: 32.790131 | E37: 33.304337 | F37: 33.675228 | G37: 33.948895 | H37: 34.370636 | I37: 34.850887 | J37: 34.987331 | K37: 35.027725 | L37: 35.055889 | M37: 35.139996 | N37: 35.184067 | O37: 35.253815 | P37: 35.313755 | Q37: 35.395432 | R37: 35.447819 | S37: 35.509632 | T37: 35.58049 | U37: 35.672146 | V37: 35.736599 | W37: 35.81567 | X37: 35.86631 | Y37: 35.911537 | Z37: 35.962078 | AA37: 36.021683 | AB37: 36.09063 | AC37: 36.147751 | AD37: 36.213341 | AE37: 36.274784 | AF37: 36.358318 | AG37: 36.442936 | AH37: 0.00459
A38: TKI000:ca_TestedNewVeh | B38: Tested New Light-Duty Vehicle 4/ | C38: 35.306622 | D38: 36.467899 | E38: 37.145805 | F38: 37.564754 | G38: 37.869587 | H38: 38.261166 | I38: 38.678329 | J38: 38.78212 | K38: 38.833714 | L38: 38.876083 | M38: 39.031017 | N38: 39.097122 | O38: 39.178814 | P38: 39.263397 | Q38: 39.380604 | R38: 39.428646 | S38: 39.476784 | T38: 39.553841 | U38: 39.655148 | V38: 39.718605 | W38: 39.800255 | X38: 39.857685 | Y38: 39.902508 | Z38: 39.954895 | AA38: 40.024872 | AB38: 40.112934 | AC38: 40.181061 | AD38: 40.254047 | AE38: 40.320404 | AF38: 40.416508 | AG38: 40.5215 | AH38: 0.004603
A39: TKI000:ca_TestedNewCar | B39: New Car 4/ | C39: 42.996372 | D39: 44.88583 | E39: 45.388092 | F39: 46.068283 | G39: 46.702301 | H39: 47.265957 | I39: 47.99147 | J39: 48.105293 | K39: 48.179577 | L39: 48.231701 | M39: 48.343479 | N39: 48.473526 | O39: 48.589264 | P39: 48.747791 | Q39: 48.918312 | R39: 49.08532 | S39: 49.232788 | T39: 49.410698 | U39: 49.605431 | V39: 49.791992 | W39: 49.975594 | X39: 50.118858 | Y39: 50.253036 | Z39: 50.390747 | AA39: 50.551331 | AB39: 50.726044 | AC39: 50.913406 | AD39: 51.097149 | AE39: 51.287189 | AF39: 51.498287 | AG39: 51.738174 | AH39: 0.006188
A40: TKI000:ca_TestedNewTwuk | B40: New Light Truck 4/ | C40: 31.69734 | D40: 32.714512 | E40: 33.224262 | F40: 33.594929 | G40: 33.868374 | H40: 34.261593 | I40: 34.620468 | J40: 34.71925 | K40: 34.751755 | L40: 34.772854 | M40: 34.839573 | N40: 34.86882 | O40: 34.918171 | P40: 34.957504 | Q40: 35.015827 | R40: 35.049236 | S40: 35.091114 | T40: 35.140182 | U40: 35.208858 | V40: 35.253445 | W40: 35.311043 | X40: 35.348305 | Y40: 35.381889 | Z40: 35.41943 | AA40: 35.464706 | AB40: 35.517353 | AC40: 35.560341 | AD40: 35.610996 | AE40: 35.657856 | AF40: 35.722626 | AG40: 35.788242 | AH40: 0.004054
A41: TKI000:ca_OnRoadNewVeh | B41: On-Road New Light-Duty Vehicle 5/ | C41: 28.801699 | D41: 29.748508 | E41: 30.302168 | F41: 30.643736 | G41: 30.892097 | H41: 31.211321 | I41: 31.551422 | J41: 31.636091 | K41: 31.678196 | L41: 31.712803 | M41: 31.839462 | N41: 31.893412 | O41: 31.960094 | P41: 32.029114 | Q41: 32.124813 | R41: 32.16391 | S41: 32.203083 | T41: 32.2659 | U41: 32.348515 | V41: 32.400196 | W41: 32.466755 | X41: 32.513561 | Y41: 32.550056 | Z41: 32.592743 | AA41: 32.649788 | AB41: 32.721619 | AC41: 32.77713 | AD41: 32.836617 | AE41: 32.890667 | AF41: 32.969021 | AG41: 33.054626 | AH41: 0.004601
A42: TKI000:ca_OnRoadNewCar | B42: New Car 5/ | C42: 35.111473 | D42: 36.65443 | E42: 37.064587 | F42: 37.620041 | G42: 38.137787 | H42: 38.598076 | I42: 39.190544 | J42: 39.283493 | K42: 39.344154 | L42: 39.386719 | M42: 39.477997 | N42: 39.584198 | O42: 39.678711 | P42: 39.808167 | Q42: 39.947414 | R42: 40.083797 | S42: 40.20422 | T42: 40.349506 | U42: 40.508526 | V42: 40.660873 | W42: 40.810806 | X42: 40.927799 | Y42: 41.037373 | Z42: 41.149826 | AA42: 41.280964 | AB42: 41.423634 | AC42: 41.576637 | AD42: 41.726685 | AE42: 41.881874 | AF42: 42.05426 | AG42: 42.250156 | AH42: 0.006188
A43: TKI000:ca_OnRoadNewTwuk | B43: New Light Truck 5/ | C43: 25.844681 | D43: 26.67404 | E43: 27.08967 | F43: 27.391895 | G43: 27.614851 | H43: 27.935465 | I43: 28.228077 | J43: 28.30862 | K43: 28.335123 | L43: 28.352325 | M43: 28.406727 | N43: 28.430573 | O43: 28.470812 | P43: 28.502882 | Q43: 28.550436 | R43: 28.577677 | S43: 28.611822 | T43: 28.651831 | U43: 28.707827 | V43: 28.744179 | W43: 28.791143 | X43: 28.821524 | Y43: 28.848907 | Z43: 28.879517 | AA43: 28.916433 | AB43: 28.95936 | AC43: 28.99441 | AD43: 29.035711 | AE43: 29.073919 | AF43: 29.12673 | AG43: 29.180231 | AH43: 0.004054
... A47: TKI000:ca_FreightTruck | B47: Freight Truck | C47: 7.238182 | D47: 7.310616 | E47: 7.389947 | F47: 7.476684 | G47: 7.574702 | H47: 7.686319 | I47: 7.80973 | J47: 7.944551 | K47: 8.083447 | L47: 8.230841 | M47: 8.382581 | N47: 8.536425 | O47: 8.686997 | P47: 8.827357 | Q47: 8.956337 | R47: 9.073474 | S47: 9.178899 | T47: 9.273054 | U47: 9.358724 | V47: 9.437573 | W47: 9.508476 | X47: 9.572987 | Y47: 9.62975 | Z47: 9.67997 | AA47: 9.724974 | AB47: 9.767028 | AC47: 9.806892 | AD47: 9.846315 | AE47: 9.885777 | AF47: 9.92395 | AG47: 9.961658 | AH47: 0.010703
B48: (seat miles per gallon)
A49: TKI000:ca_Aircraft | B49: Aircraft | C49: 71.028343 | D49: 72.22039 | E49: 72.564766 | F49: 73.078918 | G49: 73.855469 | H49: 74.440651 | I49: 74.946922 | J49: 75.432518 | K49: 75.920792 | L49: 76.399239 | M49: 76.903839 | N49: 77.42765 | O49: 77.983635 | P49: 78.569893 | Q49: 79.171509 | R49: 79.79718 | S49: 80.421959 | T49: 81.046387 | U49: 81.662766 | V49: 82.260727 | W49: 82.849083 | X49: 83.43293 | Y49: 84.016846 | Z49: 84.607124 | AA49: 85.178467 | AB49: 85.733246 | AC49: 86.278442 | AD49: 86.813042 | AE49: 87.369904 | AF49: 87.921379 | AG49: 88.469986 | AH49: 0.007346
...

Sheet AEO 2021 Table 35
E1: 2020 | F1: 2021 | G1: 2022 | H1: 2023 | I1: 2024 | J1: 2025 | K1: 2026 | L1: 2027 | M1: 2028 | N1: 2029 | O1: 2030 | P1: 2031 | Q1: 2032 | R1: 2033 | S1: 2034 | T1: 2035 | U1: 2036 | V1: 2037 | W1: 2038 | X1: 2039 | Y1: 2040 | Z1: 2041 | AA1: 2042 | AB1: 2043 | AC1: 2044 | AD1: 2045 | AE1: 2046 | AF1: 2047 | AG1: 2048 | AH1: 2049 | AI1: 2050 | AJ1: Growth (2020-2050)
A10: Table 35. Transportation Sector Energy Use by Mode and Type
A11: https://www.eia.gov/outlooks/aeo/data/browser/#/?id=45-AEO2021&region=0-0&cases=highogs&start=2019&end=2050&f=A&sourcekey=0
A12: Mon Mar 08 2021 15:04:42 GMT-0800 (Pacific Standard Time)
A13: Source: U.S. Energy Information Administration
B14: full name | C14: api key | D14: units | E14: 2020 | F14: 2021 | G14: 2022 | H14: 2023 | I14: 2024 | J14: 2025 | K14: 2026 | L14: 2027 | M14: 2028 | N14: 2029 | O14: 2030 | P14: 2031 | Q14: 2032 | R14: 2033 | S14: 2034 | T14: 2035 | U14: 2036 | V14: 2037 | W14: 2038 | X14: 2039 | Y14: 2040 | Z14: 2041 | AA14: 2042 | AB14: 2043 | AC14: 2044 | AD14: 2045 | AE14: 2046 | AF14: 2047 | AG14: 2048 | AH14: 2049 | AI14: 2050 | AJ14: Growth (2020-2050)
A15: Energy Use by Mode | C15: 45-AEO2021.2.
A16: Highway | C16: 45-AEO2021.3.
A17: Light-Duty Vehicles | B17: Transportation Energy Use: Highway: Light-Duty Vehicles: High oil and gas supply | C17: 45-AEO2021.4.highogs-d120120a | D17: trillion Btu | E17: 13684.959 | F17: 14333.232 | G17: 14327.021 | H17: 14365.353 | I17: 14366.454 | J17: 14341.867 | K17: 14287.134 | L17: 14207.24 | M17: 14125.377 | N17: 14028.782 | O17: 13931.946 | P17: 13831.038 | Q17: 13740.6 | R17: 13671.223 | S17: 13614.178 | T17: 13578.905 | U17: 13555.065 | V17: 13533.014 | W17: 13512.937 | X17: 13507.699 | Y17: 13519.428 | Z17: 13531.689 | AA17: 13551.022 | AB17: 13573.049 | AC17: 13591.697 | AD17: 13608.703 | AE17: 13631.723 | AF17: 13650.464 | AG17: 13676.699 | AH17: 13706.515 | AI17: 13736.45 | AJ17: 0
A18: Automobiles | B18: Transportation Energy Use: Highway: Light-Duty Vehicles: Automobiles: High oil and gas supply | C18: 45-AEO2021.5.highogs-d120120a | D18: trillion Btu | E18: 5675.0977 | F18: 5849.8979 | G18: 5755.2529 | H18: 5674.1973 | I18: 5571.2588 | J18: 5452.5518 | K18: 5322.6035 | L18: 5185.96 | M18: 5050.46 | N18: 4913.0923 | O18: 4785.4287 | P18: 4662.6523 | Q18: 4550.6763 | R18: 4453.6479 | S18: 4370.249 | T18: 4301.7231 | U18: 4245.416 | V18: 4198.5293 | W18: 4159.6685 | X18: 4129.9312 | Y18: 4109.8428 | Z18: 4093.1614 | AA18: 4081.1697 | AB18: 4071.9587 | AC18: 4063.4624 | AD18: 4055.2773 | AE18: 4048.9263 | AF18: 4041.3586 | AG18: 4035.5654 | AH18: 4031.2227 | AI18: 4027.0671 | AJ18: -0.011
A19: Light Trucks | B19: Transportation Energy Use: Highway: Light-Duty Vehicles: Light Trucks: High oil and gas supply | C19: 45-AEO2021.6.highogs-d120120a | D19: trillion Btu | E19: 7993.563 | F19: 8466.5332 | G19: 8555.2402 | H19: 8674.8594 | I19: 8779.1953 | J19: 8873.6572 | K19: 8949.2451 | L19: 9006.3877 | M19: 9060.4141 | N19: 9101.5811 | O19: 9132.7764 | P19: 9154.9971 | Q19: 9176.8564 | R19: 9204.7871 | S19: 9231.3809 | T19: 9264.832 | U19: 9297.46 | V19: 9322.4297 | W19: 9341.3252 | X19: 9365.9111 | Y19: 9397.7852 | Z19: 9426.7773 | AA19: 9458.1357 | AB19: 9489.3994 | AC19: 9516.5684 | AD19: 9541.7832 | AE19: 9571.1719 | AF19: 9597.5029 | AG19: 9629.5479 | AH19: 9663.7188 | AI19: 9697.8213 | AJ19: 0.006
A20: Motorcycles | B20: Transportation Energy Use: Highway: Light-Duty Vehicles: Motorcycles: High oil and gas supply | C20: 45-AEO2021.7.highogs-d120120a | D20: trillion Btu | E20: 16.299149 | F20: 16.800869 | G20: 16.528765 | H20: 16.295639 | I20: 15.999691 | J20: 15.658419 | K20: 15.284882 | L20: 14.89215 | M20: 14.502714 | N20: 14.107929 | O20: 13.741054 | P20: 13.388216 | Q20: 13.066401 | R20: 12.787572 | S20: 12.547906 | T20: 12.350933 | U20: 12.189022 | V20: 12.054244 | W20: 11.942542 | X20: 11.85706 | Y20: 11.799364 | Z20: 11.751442 | AA20: 11.71702 | AB20: 11.690611 | AC20: 11.666224 | AD20: 11.642757 | AE20: 11.624537 | AF20: 11.602818 | AG20: 11.586204 | AH20: 11.573715 | AI20: 11.561806 | AJ20: -0.011
A21: Commercial Light Trucks | B21: Transportation Energy Use: Highway: Commercial Light Trucks: High oil and gas supply | C21: 45-AEO2021.8.highogs-d120120a | D21: trillion Btu | E21: 800.59766 | F21: 824.58264 | G21: 837.18012 | H21: 842.73663 | I21: 851.00818 | J21: 861.96362 | K21: 867.17664 | L21: 868.25635 | M21: 868.72144 | N21: 868.14349 | O21: 868.26971 | P21: 869.091 | Q21: 871.65924 | R21: 875.05597 | S21: 880.52374 | T21: 888.54584 | U21: 896.60486 | V21: 904.57898 | W21: 913.07678 | X21: 922.39557 | Y21: 932.01129 | Z21: 942.83514 | AA21: 953.38037 | AB21: 965.23499 | AC21: 976.00677 | AD21: 987.21423 | AE21: 999.34717 | AF21: 1008.7945 | AG21: 1019.4604 | AH21: 1031.4871 | AI21: 1044.0883 | AJ21: 0.009
A22: Buses | B22: Transportation Energy Use: Highway: Buses: High oil and gas supply | C22: 45-AEO2021.9.highogs-d120120a | D22: trillion Btu | E22: 123.60058 | F22: 155.22908 | G22: 178.08673 | H22: 194.79402 | I22: 207.08707 | J22: 215.93285 | K22: 222.4467 | L22: 227.38673 | M22: 229.82677 | N22: 231.57542 | O22: 233.38449 | P22: 233.90918 | Q22: 234.57722 | R22: 234.89816 | S22: 235.11737 | T22: 234.73181 | U22: 234.535 | V22: 234.32896 | W22: 233.97902 | X22: 233.39026 | Y22: 232.92192 | Z22: 232.25186 | AA22: 231.51384 | AB22: 230.76698 | AC22: 230.02493 | AD22: 229.27586 | AE22: 228.442 | AF22: 227.6967 | AG22: 226.85817 | AH22: 226.28667 | AI22: 225.79506 | AJ22: 0.02
A23: Transit | B23: Transportation Energy Use: Highway: Buses: Transit: High oil and gas supply | C23: 45-AEO2021.10.highogs-d120120a | D23: trillion Btu | E23: 65.868385 | F23: 77.343925 | G23: 85.037193 | H23: 90.397377 | I23: 94.148392 | J23: 96.454201 | K23: 98.028534 | L23: 99.228485 | M23: 98.787506 | N23: 98.326218 | O23: 98.456612 | P23: 97.730179 | Q23: 97.429573 | R23: 97.078491 | S23: 96.865768 | T23: 96.19072 | U23: 95.827606 | V23: 95.546768 | W23: 95.188217 | X23: 94.635986 | Y23: 94.23497 | Z23: 93.65612 | AA23: 93.025208 | AB23: 92.393784 | AC23: 91.770996 | AD23: 91.134651 | AE23: 90.408363 | AF23: 89.765427 | AG23: 89.013596 | AH23: 88.517876 | AI23: 88.092033 | AJ23: 0.01
A24: Intercity | B24: Transportation Energy Use: Highway: Buses: Intercity: High oil and gas supply | C24: 45-AEO2021.11.highogs-d120120a | D24: trillion Btu | E24: 21.389296 | F24: 24.819853 | G24: 27.510082 | H24: 29.622658 | I24: 31.287823 | J24: 32.605827 | K24: 33.663296 | L24: 34.520813 | M24: 35.224197 | N24: 35.81303 | O24: 36.317593 | P24: 36.759636 | Q24: 37.152344 | R24: 37.510296 | S24: 37.844872 | T24: 38.157986 | U24: 38.449917 | V24: 38.72361 | W24: 38.985104 | X24: 39.238808 | Y24: 39.486942 | Z24: 39.72662 | AA24: 39.958668 | AB24: 40.184944 | AC24: 40.404293 | AD24: 40.622166 | AE24: 40.834713 | AF24: 41.040451 | AG24: 41.248081 | AH24: 41.453495 | AI24: 41.657665 | AJ24: 0.022
A25: School | B25: Transportation Energy Use: Highway: Buses: School: High oil and gas supply | C25: 45-AEO2021.12.highogs-d120120a | D25: trillion Btu | E25: 36.342903 | F25: 53.065319 | G25: 65.539474 | H25: 74.77401 | I25: 81.650841 | J25: 86.872803 | K25: 90.754913 | L25: 93.637444 | M25: 95.815033 | N25: 97.436134 | O25: 98.610291 | P25: 99.419357 | Q25: 99.995285 | R25: 100.30936 | S25: 100.40678 | T25: 100.38309 | U25: 100.25748 | V25: 100.05856 | W25: 99.805702 | X25: 99.51545 | Y25: 99.200005 | Z25: 98.869118 | AA25: 98.529976 | AB25: 98.188255 | AC25: 97.849648 | AD25: 97.519051 | AE25: 97.198906 | AF25: 96.890816 | AG25: 96.596497 | AH25: 96.315292 | AI25: 96.04538 | AJ25: 0.033
A26: Freight Trucks | B26: Transportation Energy Use: Highway: Freight Trucks: High oil and gas supply | C26: 45-AEO2021.13.highogs-d120120a | D26: trillion Btu | E26: 5217.8584 | F26: 5322.7695 | G26: 5462.249 | H26: 5509.6768 | I26: 5566.189 | J26: 5614.4268 | K26: 5611.2627 | L26: 5579.9849 | M26: 5546.2661 | N26: 5504.2886 | O26: 5469.7124 | P26: 5438.3926 | Q26: 5413.3032 | R26: 5386.6934 | S26: 5378.145 | T26: 5393.2607 | U26: 5407.6289 | V26: 5423.5879 | W26: 5448.6401 | X26: 5481.9277 | Y26: 5512.1758 | Z26: 5555.085 | AA26: 5607.7852 | AB26: 5675.5957 | AC26: 5732.5215 | AD26: 5793.834 | AE26: 5843.8721 | AF26: 5892.3438 | AG26: 5949.0996 | AH26: 6010.8965 | AI26: 6080.1992 | AJ26: 0.005
A27: Light Medium | B27: Transportation Energy Use: Highway: Freight Trucks: Light Medium: High oil and gas supply | C27: 45-AEO2021.14.highogs-d120120a | D27: trillion Btu | E27: 623.06995 | F27: 645.39587 | G27: 666.46094 | H27: 672.76428 | I27: 679.08014 | J27: 685.09302 | K27: 686.81488 | L27: 689.4306 | M27: 695.90314 | N27: 704.39606 | O27: 715.78516 | P27: 728.40607 | Q27: 741.20001 | R27: 752.46381 | S27: 764.91388 | T27: 778.96106 | U27: 790.86975 | V27: 801.79034 | W27: 813.50751 | X27: 825.59967 | Y27: 835.62042 | Z27: 847.15546 | AA27: 859.51312 | AB27: 873.85864 | AC27: 886.58179 | AD27: 900.4129 | AE27: 912.65735 | AF27: 925.97638 | AG27: 941.71063 | AH27: 957.63281 | AI27: 974.67029 | AJ27: 0.015
A28: Medium | B28: Transportation Energy Use: Highway: Freight Trucks: Medium: High oil and gas supply | C28: 45-AEO2021.15.highogs-d120120a | D28: trillion Btu | E28: 857.06537 | F28: 869.86615 | G28: 890.51807 | H28: 896.80109 | I28: 905.21356 | J28: 912.46588 | K28: 913.59228 | L28: 912.76141 | M28: 914.32025 | N28: 915.86731 | O28: 919.06012 | P28: 922.55646 | Q28: 927.62286 | R28: 931.74396 | S28: 938.57819 | T28: 949.5282 | U28: 960.74689 | V28: 973.51715 | W28: 988.40875 | X28: 1006.5817 | Y28: 1024.9167 | Z28: 1046.2407 | AA28: 1069.5592 | AB28: 1096.8451 | AC28: 1122.9235 | AD28: 1150.4531 | AE28: 1176.5758 | AF28: 1203.0889 | AG28: 1232.1707 | AH28: 1263.6315 | AI28: 1297.5896 | AJ28: 0.014
A29: Large (> 26000 pounds) | B29: Transportation Energy Use: Highway: Freight Trucks: Large: High oil and gas supply | C29: 45-AEO2021.16.highogs-d120120a | D29: trillion Btu | E29: 3737.7229 | F29: 3807.5073 | G29: 3905.2695 | H29: 3940.1116 | I29: 3981.8948 | J29: 4016.8679 | K29: 4010.8555 | L29: 3977.7935 | M29: 3936.0427 | N29: 3884.0256 | O29: 3834.8677 | P29: 3787.4297 | Q29: 3744.4802 | R29: 3702.4858 | S29: 3674.6531 | T29: 3664.7715 | U29: 3656.0122 | V29: 3648.28 | W29: 3646.7239 | X29: 3649.7461 | Y29: 3651.6387 | Z29: 3661.6887 | AA29: 3678.7134 | AB29: 3704.8914 | AC29: 3723.0164 | AD29: 3742.968 | AE29: 3754.6394 | AF29: 3763.2793 | AG29: 3775.218 | AH29: 3789.6326 | AI29: 3807.9399 | AJ29: 0.001
A30: Non-Highway | C30: 45-AEO2021.18.
A31: Air | B31: Transportation Energy Use: Non-Highway: Air: High oil and gas supply | C31: 45-AEO2021.19.highogs-d120120a | D31: trillion Btu | E31: 1860.4854 | F31: 2530.9844 | G31: 2826.3455 | H31: 2963.3054 | I31: 3051.7676 | J31: 3120.2192 | K31: 3144.2419 | L31: 3161.6294 | M31: 3182.7922 | N31: 3201.8508 | O31: 3222.4722 | P31: 3248.7065 | Q31: 3287.2988 | R31: 3325.2964 | S31: 3367.7896 | T31: 3416.8149 | U31: 3457.4727 | V31: 3492.2017 | W31: 3528.9043 | X31: 3570.2961 | Y31: 3622.0222 | Z31: 3669.8469 | AA31: 3718.9998 | AB31: 3765.7593 | AC31: 3814.1929 | AD31: 3866.814 | AE31: 3914.7515 | AF31: 3951.364 | AG31: 3990.6257 | AH31: 4026.4133 | AI31: 4062.8081 | AJ31: 0.026
A32: General Aviation | B32: Transportation Energy Use: Non-Highway: Air: General Aviation: High oil and gas supply | C32: 45-AEO2021.20.highogs-d120120a | D32: trillion Btu | E32: 109.97633 | F32: 141.88948 | G32: 155.94163 | H32: 162.45311 | I32: 166.65692 | J32: 169.90941 | K32: 171.04748 | L32: 171.87045 | M32: 172.87425 | N32: 173.77844 | O32: 174.75746 | P32: 176.00456 | Q32: 177.84047 | R32: 179.64813 | S32: 181.67046 | T32: 184.0038 | U32: 185.9389 | V32: 187.59193 | W32: 189.3391 | X32: 191.30975 | Y32: 193.77246 | Z32: 196.04944 | AA32: 198.38971 | AB32: 200.61627 | AC32: 202.92221 | AD32: 205.4279 | AE32: 207.71048 | AF32: 209.45377 | AG32: 211.3233 | AH32: 213.02757 | AI32: 214.76041 | AJ32: 0.023
A33: Domestic Passenger | B33: Transportation Energy Use: Non-Highway: Air: Domestic Passenger: High oil and gas supply | C33: 45-AEO2021.21.highogs-d120120a | D33: trillion Btu | E33: 1029.3035 | F33: 1377.4302 | G33: 1491.1099 | H33: 1527.3287 | I33: 1540.603 | J33: 1575.2826 | K33: 1594.6243 | L33: 1603.1229 | M33: 1606.5917 | N33: 1607.7135 | O33: 1610.0349 | P33: 1616.2908 | Q33: 1629.0068 | R33: 1642.5435 | S33: 1659.3156 | T33: 1678.5675 | U33: 1694.2118 | V33: 1706.4603 | W33: 1719.7704 | X33: 1737.08 | Y33: 1758.8617 | Z33: 1779.666 | AA33: 1799.6539 | AB33: 1818.678 | AC33: 1836.4475 | AD33: 1856.6439 | AE33: 1873.9916 | AF33: 1887.5896 | AG33: 1904.7295 | AH33: 1921.5889 | AI33: 1938.8723 | AJ33: 0.021
A34: International Passenger | B34: Transportation Energy Use: Non-Highway: Air: International Passenger: High oil and gas supply | C34: 45-AEO2021.22.highogs-d120120a | D34: trillion Btu | E34: 162.01057 | F34: 492.52274 | G34: 669.41522 | H34: 750.97778 | I34: 811.16065 | J34: 837.4071 | K34: 840.55621 | L34: 845.41003 | M34: 854.7381 | N34: 864.04321 | O34: 873.57477 | P34: 884.18176 | Q34: 898.26648 | R34: 911.64954 | S34: 925.93701 | T34: 942.49945 | U34: 956.36585 | V34: 968.7132 | W34: 981.62439 | X34: 995.19794 | Y34: 1012.1129 | Z34: 1027.5292 | AA34: 1044.0427 | AB34: 1059.8073 | AC34: 1076.9177 | AD34: 1095.1249 | AE34: 1112.1973 | AF34: 1125.2657 | AG34: 1138.3204 | AH34: 1149.8088 | AI34: 1161.4449 | AJ34: 0.068
A35: Dedicated Freight | B35: Transportation Energy Use: Non-Highway: Air: Dedicated Freight: High oil and gas supply | C35: 45-AEO2021.23.highogs-d120120a | D35: trillion Btu | E35: 559.19495 | F35: 519.14203 | G35: 509.87872 | H35: 522.54559 | I35: 533.34705 | J35: 537.62024 | K35: 538.01386 | L35: 541.22595 | M35: 548.58813 | N35: 556.31574 | O35: 564.1051 | P35: 572.22961 | Q35: 582.18518 | R35: 591.45514 | S35: 600.86682 | T35: 611.74402 | U35: 620.95605 | V35: 629.43628 | W35: 638.17041 | X35: 646.7085 | Y35: 657.27508 | Z35: 666.6023 | AA35: 676.91339 | AB35: 686.65765 | AC35: 697.90521 | AD35: 709.61707 | AE35: 720.85217 | AF35: 729.05499 | AG35: 736.25275 | AH35: 741.98798 | AI35: 747.73035 | AJ35: 0.01
A36: Water | B36: Transportation Energy Use: Non-Highway: Water: High oil and gas supply | C36: 45-AEO2021.24.highogs-d120120a | D36: trillion Btu | E36: 1129.1088 | F36: 1157.2632 | G36: 1251.9425 | H36: 1271.0579 | I36: 1220.1064 | J36: 1222.1813 | K36: 1231.5403 | L36: 1205.2488 | M36: 1202.4742 | N36: 1190.4596 | O36: 1189.082 | P36: 1203.5217 | Q36: 1186.6602 | R36: 1184.9104 | S36: 1180.7228 | T36: 1193.8921 | U36: 1177.7051 | V36: 1175.0314 | W36: 1182.9781 | X36: 1167.7097 | Y36: 1164.3445 | Z36: 1175.8888 | AA36: 1158.8889 | AB36: 1157.1489 | AC36: 1149.3973 | AD36: 1148.7852 | AE36: 1143.7438 | AF36: 1139.9766 | AG36: 1139.2001 | AH36: 1136.608 | AI36: 1132.9697 | AJ36: 0
A37: Freight | B37: Transportation Energy Use: Non-Highway: Water: Freight: High oil and gas supply | C37: 45-AEO2021.25.highogs-d120120a | D37: trillion Btu | E37: 933.23035 | F37: 960.6062 | G37: 1052.2262 | H37: 1069.5435 | I37: 1017.8489 | J37: 1019.6077 | K37: 1029.6858 | L37: 1004.8707 | M37: 1003.7998 | N37: 993.62921 | O37: 994.01324 | P37: 1009.9661 | Q37: 994.1709 | R37: 993.52716 | S37: 990.23901 | T37: 1004.0739 | U37: 988.7948 | V37: 987.27228 | W37: 996.31964 | X37: 981.9082 | Y37: 979.12146 | Z37: 991.30054 | AA37: 975.00702 | AB37: 973.97424 | AC37: 967.06848 | AD37: 967.10553 | AE37: 962.83832 | AF37: 960.09705 | AG37: 960.05969 | AH37: 958.24249 | AI37: 955.39801 | AJ37: 0.001
A38: Domestic Shipping | B38: Transportation Energy Use: Non-Highway: Water: Freight: Domestic Shipping: High oil and gas supply | C38: 45-AEO2021.26.highogs-d120120a | D38: trillion Btu | E38: 77.343407 | F38: 79.141403 | G38: 78.228264 | H38: 77.350044 | I38: 76.446533 | J38: 75.055573 | K38: 73.204681 | L38: 71.058418 | M38: 68.994972 | N38: 66.833633 | O38: 64.753128 | P38: 63.638058 | Q38: 62.605038 | R38: 61.510983 | S38: 60.561947 | T38: 59.665359 | U38: 58.721436 | V38: 57.711258 | W38: 56.658974 | X38: 55.745102 | Y38: 54.692238 | Z38: 54.265388 | AA38: 53.873783 | AB38: 53.634262 | AC38: 53.239914 | AD38: 52.87286 | AE38: 52.373196 | AF38: 51.890907 | AG38: 51.370388 | AH38: 50.910122 | AI38: 50.533489 | AJ38: -0.014
A39: International Shipping | B39: Transportation Energy Use: Non-Highway: Water: Freight: International Shipping: High oil and gas supply | C39: 45-AEO2021.27.highogs-d120120a | D39: trillion Btu | E39: 855.88696 | F39: 881.46478 | G39: 973.99793 | H39: 992.19336 | I39: 941.40234 | J39: 944.55212 | K39: 956.48108 | L39: 933.81226 | M39: 934.80481 | N39: 926.79559 | O39: 929.26013 | P39: 946.32806 | Q39: 931.56586 | R39: 932.01617 | S39: 929.67706 | T39: 944.40857 | U39: 930.07336 | V39: 929.56103 | W39: 939.66065 | X39: 926.16309 | Y39: 924.4292 | Z39: 937.03516 | AA39: 921.13324 | AB39: 920.33997 | AC39: 913.82855 | AD39: 914.23267 | AE39: 910.46515 | AF39: 908.20612 | AG39: 908.68933 | AH39: 907.3324 | AI39: 904.8645 | AJ39: 0.002
A40: Recreational Boats | B40: Transportation Energy Use: Non-Highway: Water: Recreational Boats: High oil and gas supply | C40: 45-AEO2021.28.highogs-d120120a | D40: trillion Btu | E40: 195.87843 | F40: 196.65694 | G40: 199.71631 | H40: 201.51434 | I40: 202.25748 | J40: 202.57369 | K40: 201.85445 | L40: 200.37804 | M40: 198.67445 | N40: 196.83032 | O40: 195.06877 | P40: 193.55562 | Q40: 192.48926 | R40: 191.38321 | S40: 190.48383 | T40: 189.81821 | U40: 188.91023 | V40: 187.75908 | W40: 186.65848 | X40: 185.8015 | Y40: 185.22307 | Z40: 184.58832 | AA40: 183.88181 | AB40: 183.17465 | AC40: 182.32883 | AD40: 181.67963 | AE40: 180.9055 | AF40: 179.87953 | AG40: 179.14038 | AH40: 178.36557 | AI40: 177.57169 | AJ40: -0.003
A41: Rail | B41: Transportation Energy Use: Non-Highway: Rail: High oil and gas supply | C41: 45-AEO2021.29.highogs-d120120a | D41: trillion Btu | E41: 461.76639 | F41: 491.05136 | G41: 497.25409 | H41: 498.29584 | I41: 498.00287 | J41: 483.20465 | K41: 487.16257 | L41: 485.19531 | M41: 488.07013 | N41: 490.24463 | O41: 492.73157 | P41: 493.54889 | Q41: 493.9744 | R41: 495.27838 | S41: 495.26675 | T41: 496.70953 | U41: 497.9765 | V41: 498.69684 | W41: 497.479 | X41: 499.69305 | Y41: 499.10703 | Z41: 500.07611 | AA41: 502.25479 | AB41: 505.43637 | AC41: 504.1955 | AD41: 505.57495 | AE41: 505.80637 | AF41: 507.0365 | AG41: 508.25165 | AH41: 509.73273 | AI41: 512.97174 | AJ41: 0.004
A42: Freight | B42: Transportation Energy Use: Non-Highway: Rail: Freight: High oil and gas supply | C42: 45-AEO2021.30.highogs-d120120a | D42: trillion Btu | E42: 432.32916 | F42: 455.80057 | G42: 457.32019 | H42: 454.81757 | I42: 451.84665 | J42: 435.03867 | K42: 437.54752 | L42: 434.49982 | M42: 437.06894 | N42: 438.99457 | O42: 440.98004 | P42: 441.53027 | Q42: 441.40082 | R42: 442.16769 | S42: 441.50205 | T42: 442.37979 | U42: 443.02426 | V42: 443.14713 | W42: 441.33752 | X42: 442.94101 | Y42: 441.56534 | Z42: 441.80859 | AA42: 443.27573 | AB42: 445.72418 | AC42: 443.77713 | AD42: 444.37201 | AE42: 443.88855 | AF42: 444.47339 | AG42: 444.99793 | AH42: 445.72116 | AI42: 448.21558 | AJ42: 0.001
... A53: Total | B53: Transportation Energy Use: Total: High oil and gas supply | C53: 45-AEO2021.43.highogs-d120120a | D53: trillion Btu | E53: 24641.816 | F53: 26248.666 | G53: 26805.998 | H53: 27035.342 | I53: 27134.359 | J53: 27234.799 | K53: 27191.32 | L53: 27084.865 | M53: 26996.002 | N53: 26866.41 | O53: 26748.799 | P53: 26660.07 | Q53: 26573.197 | R53: 26520.012 | S53: 26498.09 | T53: 26553.664 | U53: 26586.883 | V53: 26631.479 | W53: 26696.67 | X53: 26767.367 | Y53: 26871.051 | Z53: 27000.164 | AA53: 27121.412 | AB53: 27278.543 | AC53: 27415.6 | AD53: 27565.312 | AE53: 27701.846 | AF53: 27821.959 | AG53: 27950.746 | AH53: 28088.564 | AI53: 28244.232 | AJ53: 0.005
A54: Energy Use by Type | C54: 45-AEO2021.45.
A55: Motor Gasoline excluding E85 | B55: Transportation Energy Use: Petroleum: Motor Gasoline: High oil and gas supply | C55: 45-AEO2021.46.highogs-d120120a | D55: trillion Btu | E55: 14809.331 | F55: 15470.562 | G55: 15477.318 | H55: 15509.706 | I55: 15508.433 | J55: 15483.517 | K55: 15421.747 | L55: 15333.079 | M55: 15245.05 | N55: 15143.332 | O55: 15043.969 | P55: 14940.797 | Q55: 14850.533 | R55: 14780.868 | S55: 14725.552 | T55: 14695.301 | U55: 14674.445 | V55: 14655.884 | W55: 14640.091 | X55: 14640.239 | Y55: 14655.854 | Z55: 14675.101 | AA55: 14702.387 | AB55: 14734.696 | AC55: 14761.429 | AD55: 14788.444 | AE55: 14820.81 | AF55: 14848.021 | AG55: 14885.904 | AH55: 14929.089 | AI55: 14974.693 | AJ55: 0
A56: E85 | B56: Transportation Energy Use: E85: High oil and gas supply | C56: 45-AEO2021.47.highogs-d120120a | D56: trillion Btu | E56: 33.666061 | F56: 36.292164 | G56: 35.002701 | H56: 36.768921 | I56: 37.090172 | J56: 37.279301 | K56: 37.273434 | L56: 36.962608 | M56: 36.692116 | N56: 36.407269 | O56: 36.183594 | P56: 36.116623 | Q56: 36.088921 | R56: 36.198486 | S56: 36.388977 | T56: 36.925545 | U56: 37.477287 | V56: 38.130039 | W56: 38.828465 | X56: 39.735065 | Y56: 40.706123 | Z56: 41.727245 | AA56: 42.842529 | AB56: 43.978745 | AC56: 45.153854 | AD56: 46.265217 | AE56: 47.409328 | AF56: 48.760159 | AG56: 49.995644 | AH56: 51.544422 | AI56: 53.091187 | AJ56: 0.015
A57: Diesel | B57: Transportation Energy Use: Petroleum: Diesel: High oil and gas supply | C57: 45-AEO2021.48.highogs-d120120a | D57: trillion Btu | E57: 6144.374 | F57: 6254.561 | G57: 6296.688 | H57: 6333.9224 | I57: 6469.3887 | J57: 6508.3208 | K57: 6497.1807 | L57: 6493.1206 | M57: 6455.3403 | N57: 6414.4653 | O57: 6368.2964 | P57: 6301.3911 | Q57: 6279.1006 | R57: 6236.5176 | S57: 6213.1655 | T57: 6192.251 | U57: 6207.4717 | V57: 6203.5488 | W57: 6192.0122 | X57: 6220.2158 | Y57: 6226.5527 | Z57: 6228.9126 | AA57: 6273.5908 | AB57: 6314.6074 | AC57: 6347.5444 | AD57: 6376.3735 | AE57: 6399.9995 | AF57: 6418.7915 | AG57: 6440.9194 | AH57: 6466.8232 | AI57: 6500.1226 | AJ57: 0.002
A58: Jet Fuel (kerosene & naphtha) | B58: Transportation Energy Use: Petroleum: Jet Fuel: High oil and gas supply | C58: 45-AEO2021.49.highogs-d120120a | D58: trillion Btu | E58: 2239.7639 | F58: 2917.0544 | G58: 3212.9678 | H58: 3340.0581 | I58: 3422.0215 | J58: 3490.0879 | K58: 3513.1729 | L58: 3530.4417 | M58: 3553.7649 | N58: 3571.9607 | O58: 3591.0972 | P58: 3617.2712 | Q58: 3656.4937 | R58: 3695.1418 | S58: 3738.2942 | T58: 3787.9761 | U58: 3829.3232 | V58: 3864.7639 | W58: 3902.1855 | X58: 3944.3027 | Y58: 3996.7605 | Z58: 4045.3213 | AA58: 4095.2144 | AB58: 4142.7163 | AC58: 4191.8945 | AD58: 4245.2622 | AE58: 4293.9473 | AF58: 4331.3066 | AG58: 4371.3149 | AH58: 4407.8477 | AI58: 4444.9878 | AJ58: 0.023
...

Sheet AEO 2021 Table 46
A1: AEO.2021.HIGHOGS.ECI_VMT_NA_CLTR_TDS_NA_NA_BLNMLS.A
A2: Units | B2: billion miles
A3: A
A4: 43466 | B4: 2019-01-01 - 2050-01-01
A5: Fleet Vehicle Miles Traveled : Commercial Light Trucks : TDI Diesel, High oil and gas supply, AEO2021
A7: date | B7: value
A8: 2050 | B8: 48.533054
A9: 2049 | B9: 48.228958
A10: 2048 | B10: 47.872959
A11: 2047 | B11: 47.527718
A12: 2046 | B12: 47.220272
A13: 2045 | B13: 46.824818
A14: 2044 | B14: 46.39399
A15: 2043 | B15: 45.972202
A16: 2042 | B16: 45.519039
A17: 2041 | B17: 45.136539
A18: 2040 | B18: 44.77256
A19: 2039 | B19: 44.485531
... A38: 2020 | B38: 32.357178

Sheet AEO 2021 Table 47
E1: 2020 | F1: 2021 | G1: 2022 | H1: 2023 | I1: 2024 | J1: 2025 | K1: 2026 | L1: 2027 | M1: 2028 | N1: 2029 | O1: 2030 | P1: 2031 | Q1: 2032 | R1: 2033 | S1: 2034 | T1: 2035 | U1: 2036 | V1: 2037 | W1: 2038 | X1: 2039 | Y1: 2040 | Z1: 2041 | AA1: 2042 | AB1: 2043 | AC1: 2044 | AD1: 2045 | AE1: 2046 | AF1: 2047 | AG1: 2048 | AH1: 2049 | AI1: 2050 | AJ1: Growth (2020-2050)
A10: Table 47. Air Travel Energy Use
A11: https://www.eia.gov/outlooks/aeo/data/browser/#/?id=57-AEO2021&cases=highogs&sourcekey=0
A12: Mon Mar 08 2021 15:07:46 GMT-0800 (Pacific Standard Time)
A13: Source: U.S. Energy Information Administration
B14: full name | C14: api key | D14: units | E14: 2020 | F14: 2021 | G14: 2022 | H14: 2023 | I14: 2024 | J14: 2025 | K14: 2026 | L14: 2027 | M14: 2028 | N14: 2029 | O14: 2030 | P14: 2031 | Q14: 2032 | R14: 2033 | S14: 2034 | T14: 2035 | U14: 2036 | V14: 2037 | W14: 2038 | X14: 2039 | Y14: 2040 | Z14: 2041 | AA14: 2042 | AB14: 2043 | AC14: 2044 | AD14: 2045 | AE14: 2046 | AF14: 2047 | AG14: 2048 | AH14: 2049 | AI14: 2050 | AJ14: Growth (2020-2050)
A15: Fuel Cost (1987 dollars per million Btu) | B15: Air Travel: Fuel Cost: High oil and gas supply | C15: 57-AEO2021.2.highogs-d120120a | D15: 1987 $/MMBtu | E15: 4.815659 | F15: 5.225039 | G15: 5.661561 | H15: 6.07062 | I15: 6.344047 | J15: 6.384036 | K15: 6.625891 | L15: 6.825773 | M15: 6.943011 | N15: 7.10312 | O15: 7.293634 | P15: 7.380465 | Q15: 7.53721 | R15: 7.630815 | S15: 7.699437 | T15: 7.693654 | U15: 7.658198 | V15: 7.757175 | W15: 7.87585 | X15: 7.833405 | Y15: 8.049649 | Z15: 8.140811 | AA15: 8.218174 | AB15: 8.324425 | AC15: 8.451997 | AD15: 8.607639 | AE15: 8.685135 | AF15: 8.749039 | AG15: 8.773533 | AH15: 8.89049 | AI15: 8.968845 | AJ15: 0.021
A16: Ticket Price (1996 cents per passenger mile) | C16: 57-AEO2021.4.
A17: Domestic | B17: Air Travel: Ticket Price: Domestic: High oil and gas supply | C17: 57-AEO2021.5.highogs-d120120a | D17: 1996 cents | E17: 8.859536 | F17: 9.207203 | G17: 9.549512 | H17: 9.865418 | I17: 10.143012 | J17: 10.368609 | K17: 10.613405 | L17: 10.853698 | M17: 11.059388 | N17: 11.263126 | O17: 11.468404 | P17: 11.644133 | Q17: 11.822231 | R17: 11.981596 | S17: 12.12817 | T17: 12.254734 | U17: 12.377423 | V17: 12.518564 | W17: 12.655679 | X17: 12.75572 | Y17: 12.902014 | Z17: 13.019755 | AA17: 13.130799 | AB17: 13.245197 | AC17: 13.362012 | AD17: 13.480856 | AE17: 13.583618 | AF17: 13.678144 | AG17: 13.760929 | AH17: 13.856179 | AI17: 13.943871 | AJ17: 0.015
A18: International | B18: Air Travel: Ticket Price: International: High oil and gas supply | C18: 57-AEO2021.6.highogs-d120120a | D18: 1996 cents | E18: 11.967103 | F18: 12.894226 | G18: 13.546987 | H18: 14.025295 | I18: 14.390685 | J18: 14.679313 | K18: 14.935001 | L18: 15.16576 | M18: 15.374655 | N18: 15.575786 | O18: 15.773184 | P18: 15.961397 | Q18: 16.150122 | R18: 16.334641 | S18: 16.516947 | T18: 16.695312 | U18: 16.873196 | V18: 17.056742 | W18: 17.240631 | X18: 17.4165 | Y18: 17.605228 | Z18: 17.787903 | AA18: 17.969934 | AB18: 18.15366 | AC18: 18.338688 | AD18: 18.524971 | AE18: 18.707729 | AF18: 18.889225 | AG18: 19.068621 | AH18: 19.252192 | AI18: 19.434509 | AJ18: 0.016
A19: Non-U.S. | B19: Air Travel: Ticket Price: Non U.S.: High oil and gas supply | C19: 57-AEO2021.7.highogs-d120120a | D19: 1996 cents | E19: 11.967103 | F19: 12.894226 | G19: 13.546987 | H19: 14.025295 | I19: 14.390685 | J19: 14.679313 | K19: 14.935001 | L19: 15.16576 | M19: 15.374655 | N19: 15.575786 | O19: 15.773184 | P19: 15.961397 | Q19: 16.150122 | R19: 16.334641 | S19: 16.516947 | T19: 16.695312 | U19: 16.873196 | V19: 17.056742 | W19: 17.240631 | X19: 17.4165 | Y19: 17.605228 | Z19: 17.787903 | AA19: 17.969934 | AB19: 18.15366 | AC19: 18.338688 | AD19: 18.524971 | AE19: 18.707729 | AF19: 18.889225 | AG19: 19.068621 | AH19: 19.252192 | AI19: 19.434509 | AJ19: 0.016
A20: Load Factor (fraction of seats filled) | C20: 57-AEO2021.9.
A21: U.S. Domestic | B21: Air Travel: Load Factor: U.S. Domestic: High oil and gas supply | C21: 57-AEO2021.10.highogs-d120120a | D21: fraction | E21: 0.581099 | F21: 0.726373 | G21: 0.799011 | H21: 0.838961 | I21: 0.859821 | J21: 0.859821 | K21: 0.860774 | L21: 0.861627 | M21: 0.862389 | N21: 0.863072 | O21: 0.863687 | P21: 0.864239 | Q21: 0.86474 | R21: 0.865194 | S21: 0.865608 | T21: 0.865987 | U21: 0.866335 | V21: 0.866655 | W21: 0.866951 | X21: 0.867225 | Y21: 0.86752 | Z21: 0.867816 | AA21: 0.868112 | AB21: 0.868408 | AC21: 0.868704 | AD21: 0.869001 | AE21: 0.869297 | AF21: 0.869594 | AG21: 0.86989 | AH21: 0.870187 | AI21: 0.870484 | AJ21: 0.014
A22: U.S. International | B22: Air Travel: Load Factor: U.S. International: High oil and gas supply | C22: 57-AEO2021.11.highogs-d120120a | D22: fraction | E22: 0.67798 | F22: 0.745778 | G22: 0.797982 | H22: 0.821921 | I22: 0.824666 | J22: 0.824666 | K22: 0.824715 | L22: 0.824764 | M22: 0.82481 | N22: 0.824855 | O22: 0.8249 | P22: 0.824943 | Q22: 0.824987 | R22: 0.82503 | S22: 0.825073 | T22: 0.825116 | U22: 0.825159 | V22: 0.825201 | W22: 0.825241 | X22: 0.82528 | Y22: 0.825321 | Z22: 0.825362 | AA22: 0.825402 | AB22: 0.825443 | AC22: 0.825484 | AD22: 0.825524 | AE22: 0.825565 | AF22: 0.825606 | AG22: 0.825646 | AH22: 0.825687 | AI22: 0.825727 | AJ22: 0.007
A23: Driver Variables | C23: 57-AEO2021.13.
A24: Population (millions) | C24: 57-AEO2021.29.
A25: United States | B25: Air Travel: Drivers: Population: U.S.: High oil and gas supply | C25: 57-AEO2021.30.highogs-d120120a | D25: millions | E25: 330.40802 | F25: 332.66257 | G25: 334.98496 | H25: 337.28607 | I25: 339.56256 | J25: 341.81274 | K25: 344.03778 | L25: 346.23038 | M25: 348.38626 | N25: 350.51099 | O25: 352.59775 | P25: 354.63107 | Q25: 356.61285 | R25: 358.54746 | S25: 360.43543 | T25: 362.27774 | U25: 364.07599 | V25: 365.83209 | W25: 367.54804 | X25: 369.2262 | Y25: 370.86914 | Z25: 372.47977 | AA25: 374.06146 | AB25: 375.61777 | AC25: 377.15305 | AD25: 378.672 | AE25: 380.17905 | AF25: 381.67728 | AG25: 383.17071 | AH25: 384.66336 | AI25: 386.1586 | AJ25: 0.005
A26: Canada | B26: Air Travel: Drivers: Population: Canada: High oil and gas supply | C26: 57-AEO2021.31.highogs-d120120a | D26: millions | E26: 37.954399 | F26: 38.284569 | G26: 38.694302 | H26: 39.1026 | I26: 39.509079 | J26: 39.913521 | K26: 40.315201 | L26: 40.713902 | M26: 41.1092 | N26: 41.500671 | O26: 41.8881 | P26: 42.271 | Q26: 42.6493 | R26: 43.0228 | S26: 43.391499 | T26: 43.755501 | U26: 44.114731 | V26: 44.469398 | W26: 44.819481 | X26: 45.165298 | Y26: 45.506802 | Z26: 45.84388 | AA26: 46.176899 | AB26: 46.5056 | AC26: 46.831772 | AD26: 47.1562 | AE26: 47.479069 | AF26: 47.8008 | AG26: 48.12167 | AH26: 48.442322 | AI26: 48.763081 | AJ26: 0.008
A27: Central America | B27: Air Travel: Drivers: Population: Central America: High oil and gas supply | C27: 57-AEO2021.32.highogs-d120120a | D27: millions | E27: 223.32042 | F27: 225.61029 | G27: 227.87177 | H27: 230.10426 | I27: 232.30614 | J27: 234.4767 | K27: 236.53438 | L27: 238.5605 | M27: 240.55659 | N27: 242.52452 | O27: 244.46452 | P27: 246.26724 | Q27: 248.04324 | R27: 249.78932 | S27: 251.50108 | T27: 253.17491 | U27: 254.71349 | V27: 256.21668 | W27: 257.68503 | X27: 259.11847 | Y27: 260.51691 | Z27: 261.77008 | AA27: 262.98868 | AB27: 264.17175 | AC27: 265.32071 | AD27: 266.43298 | AE27: 267.38092 | AF27: 268.28256 | AG27: 269.15918 | AH27: 270.03339 | AI27: 270.9209 | AJ27: 0.006
A28: South America | B28: Air Travel: Drivers: Population: South America: High oil and gas supply | C28: 57-AEO2021.33.highogs-d120120a | D28: millions | E28: 430.70032 | F28: 433.89069 | G28: 437.24808 | H28: 440.69479 | I28: 444.09705 | J28: 447.36014 | K28: 450.48035 | L28: 453.44321 | M28: 456.26621 | N28: 458.98441 | O28: 461.62607 | P28: 464.07138 | Q28: 466.42432 | R28: 468.68573 | S28: 470.8587 | T28: 472.94543 | U28: 474.80039 | V28: 476.57565 | W28: 478.27377 | X28: 479.89575 | Y28: 481.44193 | Z28: 482.76858 | AA28: 484.01843 | AB28: 485.1962 | AC28: 486.30759 | AD28: 487.35217 | AE28: 488.16757 | AF28: 488.89957 | AG28: 489.58212 | AH28: 490.25284 | AI28: 490.93707 | AJ28: 0.004
A29: Europe | B29: Air Travel: Drivers: Population: Europe: High oil and gas supply | C29: 57-AEO2021.34.highogs-d120120a | D29: millions | E29: 631.30512 | F29: 632.64197 | G29: 633.69061 | H29: 634.54712 | I29: 635.32483 | J29: 636.11169 | K29: 636.90045 | L29: 637.65955 | M29: 638.40143 | N29: 639.13501 | O29: 639.86548 | P29: 640.57477 | Q29: 641.27387 | R29: 641.9436 | S29: 642.55975 | T29: 643.11066 | U29: 643.59149 | V29: 644.02026 | W29: 644.39563 | X29: 644.71454 | Y29: 644.96997 | Z29: 645.15045 | AA29: 645.26129 | AB29: 645.29871 | AC29: 645.26233 | AD29: 645.15008 | AE29: 644.94629 | AF29: 644.65442 | AG29: 644.28961 | AH29: 643.86713 | AI29: 643.39825 | AJ29: 0.001
A30: Africa | B30: Air Travel: Drivers: Population: Africa: High oil and gas supply | C30: 57-AEO2021.35.highogs-d120120a | D30: millions | E30: 1237.5863 | F30: 1269.3195 | G30: 1301.0847 | H30: 1332.8693 | I30: 1364.6515 | J30: 1396.4197 | K30: 1430.4786 | L30: 1464.5223 | M30: 1498.5533 | N30: 1532.5752 | O30: 1566.5935 | P30: 1602.6628 | Q30: 1638.724 | R30: 1674.7766 | S30: 1710.8201 | T30: 1746.8513 | U30: 1784.5621 | V30: 1822.2616 | W30: 1859.9501 | X30: 1897.6271 | Y30: 1935.2927 | Z30: 1974.2361 | AA30: 2013.1689 | AB30: 2052.0891 | AC30: 2090.9966 | AD30: 2129.8879 | AE30: 2169.5337 | AF30: 2209.1592 | AG30: 2248.7764 | AH30: 2288.3933 | AI30: 2328.0171 | AJ30: 0.021
A31: Mideast | B31: Air Travel: Drivers: Population: Mideast: High oil and gas supply | C31: 57-AEO2021.36.highogs-d120120a | D31: millions | E31: 363.01025 | F31: 370.27365 | G31: 377.6571 | H31: 384.60693 | I31: 391.44876 | J31: 398.2377 | K31: 404.39142 | L31: 410.4957 | M31: 416.58557 | N31: 422.6619 | O31: 428.73337 | P31: 434.43762 | Q31: 440.14346 | R31: 445.8414 | S31: 451.53378 | T31: 457.21707 | U31: 462.81811 | V31: 468.40582 | W31: 473.97998 | X31: 479.54068 | Y31: 485.08743 | Z31: 490.45166 | AA31: 495.79648 | AB31: 501.12061 | AC31: 506.42529 | AD31: 511.70911 | AE31: 516.69 | AF31: 521.64764 | AG31: 526.58185 | AH31: 531.48944 | AI31: 536.37134 | AJ31: 0.013
A32: Commonwealth of Independent States | B32: Air Travel: Drivers: Population: CIS: High oil and gas supply | C32: 57-AEO2021.37.highogs-d120120a | D32: millions | E32: 295.35101 | F32: 296.15237 | G32: 296.86581 | H32: 297.51209 | I32: 298.11151 | J32: 298.68005 | K32: 299.02649 | L32: 299.32474 | M32: 299.5896 | N32: 299.83374 | O32: 300.06818 | P32: 300.23135 | Q32: 300.371 | R32: 300.50034 | S32: 300.63248 | T32: 300.77875 | U32: 300.92786 | V32: 301.07996 | W32: 301.24084 | X32: 301.41635 | Y32: 301.61285 | Z32: 301.76486 | AA32: 301.93426 | AB32: 302.11798 | AC32: 302.31299 | AD32: 302.51758 | AE32: 302.60272 | AF32: 302.70096 | AG32: 302.80655 | AH32: 302.91498 | AI32: 303.01962 | AJ32: 0.001
